Workbook

Sheet Summary 1220_vs帝京
D3: 筑波大学 | I3: 0 | K3: - | M3: 36 | O3: 帝京大学 | U3: 12月20日 | Y3: 秩父宮ラグビー場 | AC3: 11:30 Kick Off | AG3: 大澤昂平
D5: Contact AT STATS | U5: Contact DF STATS
D7: Team Stats | U7: Team Stats
D9: ゲイン | J9: 継続 | P9: B2 | U9: タックル | Y9: Defeat | AC9: Contest | AG9: ゲイン
E14: =E17 -> 5 | F14: =G17-E17 -> 33 | K14: =K17 -> 43 | L14: =M17-K17 -> 14 | Q14: =Q17 -> 13 | R14: =S17-Q17 -> 32 | V14: =V17 -> 155 | W14: =X17-V17 -> 38 | Z14: =Z17 -> 10 | AA14: =AB17-Z17 -> 183 | AD14: =AD17 -> 43 | AE14: =AF17-AD17 -> 35 | AH14: =AH17 -> 12 | AI14: =AJ17-AH17 -> 30
D16: =E17/G17 -> 0.13157895 | J16: =K17/M17 -> 0.75438596 | P16: =Q17/S17 -> 0.28888889 | U16: =V17/X17 -> 0.80310881 | Y16: =Z17/AB17 -> 0.051813472 | AC16: =AD17/AF17 -> 0.55128205 | AG16: =AH17/AJ17 -> 0.28571429
D17: 成功 | E17: =J22+M22+P22 -> 5 | F17: 母数 | G17: =J23+M23+P23 -> 38 | J17: 成功 | K17: =J26+M26+P26+S26 -> 43 | L17: 母数 | M17: =J27+M27+P27+S27 -> 57 | P17: 成功 | Q17: 13 | R17: 母数 | S17: 45 | U17: 成功 | V17: ='Individual DF 1220_vs帝京'!K34+'Individual DF 1220_vs帝京'!L34+'Individual DF 1220_vs帝京'!T34+'Individual DF 1220_vs帝京'!U34 -> 155 | W17: 母数 | X17: ='Individual DF 1220_vs帝京'!G34 -> 193 | Y17: 成功 | Z17: ='Individual DF 1220_vs帝京'!K34+'Individual DF 1220_vs帝京'!T34 -> 10 | AA17: 母数 | AB17: ='Individual DF 1220_vs帝京'!G34 -> 193 | AC17: 成功 | AD17: 43 | AE17: 母数 | AF17: 78 | AG17: 成功 | AH17: 12 | AI17: 母数 | AJ17: 42
D19: Detail Stats | U19: Detail Stats
D21: ゲイン | H21: 9Shape | K21: 10Shape | N21: LineAttack | Q21: Line Atatack(1phase) | U21: タックル | Y21: FW | AB21: BK
G22: 成功 | H22: =J22/J23 -> 0.071428571 | J22: 2 | K22: =M22/M23 -> 0 | M22: 0 | N22: =P22/P23 -> 0.33333333 | P22: 3 | Q22: ー | S22: - | X22: 成功 | Y22: =AA22/AA23 -> 0.84545455 | AA22: ='Individual DF 1220_vs帝京'!K32+'Individual DF 1220_vs帝京'!L32+'Individual DF 1220_vs帝京'!T32+'Individual DF 1220_vs帝京'!U32 -> 93 | AB22: =AD22/AD23 -> 0.74698795 | AD22: ='Individual DF 1220_vs帝京'!K33+'Individual DF 1220_vs帝京'!L33+'Individual DF 1220_vs帝京'!T33+'Individual DF 1220_vs帝京'!U33 -> 62
G23: 母数 | J23: 28 | M23: 1 | P23: 9 | S23: - | X23: 母数 | AA23: ='Individual DF 1220_vs帝京'!G32 -> 110 | AD23: ='Individual DF 1220_vs帝京'!G33 -> 83
D25: 継続 | H25: 9Shape | K25: 10Shape | N25: LineAttack | Q25: Line Atatack(1phase) | U25: Defeat | Y25: FW | AB25: BK
G26: 成功 | H26: =J26/J27 -> 0.96428571 | J26: 27 | K26: =M26/M27 -> 1 | M26: 1 | N26: =P26/P27 -> 0.33333333 | P26: 3 | Q26: =S26/S27 -> 0.63157895 | S26: 12 | X26: 成功 | Y26: =AA26/AA27 -> 0.054545455 | AA26: ='Individual DF 1220_vs帝京'!K32+'Individual DF 1220_vs帝京'!T32 -> 6 | AB26: =AD26/AD27 -> 0.048192771 | AD26: ='Individual DF 1220_vs帝京'!K33+'Individual DF 1220_vs帝京'!T33 -> 4
G27: 母数 | J27: 28 | M27: 1 | P27: 9 | S27: 19 | X27: 母数 | AA27: ='Individual DF 1220_vs帝京'!G32 -> 110 | AD27: ='Individual DF 1220_vs帝京'!G33 -> 83
D29: B2,3 | H29: B3 | K29: B2 | N29: - | Q29: -
G30: 成功 | H30: =J30/J31 -> 0.62222222 | J30: 28 | K30: =M30/M31 -> 0.28888889 | M30: 13 | N30: - | P30: - | Q30: - | S30: -
G31: 母数 | J31: 45 | M31: 45 | P31: - | S31: -
D34: Set Play Stats
D36: SC Stats | U36: LO Stats
D38: SC | L38: SC マイボールキープ率 | U38: LO | AC38: LO マイボールキープ率
H39: =D3 -> 筑波大学 | J39: ='Set 1220_vs帝京'!C7 -> 6 | L39: =D3 -> 筑波大学 | P39: =O3 -> 帝京大学 | Y39: =D3 -> 筑波大学 | AA39: ='Set 1220_vs帝京'!C11 -> 19 | AC39: =D3 -> 筑波大学 | AG39: =O3 -> 帝京大学
L41: ='Set 1220_vs帝京'!D7 -> 1 | P41: ='Set 1220_vs帝京'!D17 -> 0.875 | AC41: ='Set 1220_vs帝京'!D11 -> 0.68421053 | AG41: ='Set 1220_vs帝京'!D21 -> 0.55555556
H42: =O3 -> 帝京大学 | J42: ='Set 1220_vs帝京'!C17 -> 8 | Y42: =O3 -> 帝京大学 | AA42: ='Set 1220_vs帝京'!C21 -> 18
E43: =J39 -> 6 | F43: =J42 -> 8 | V43: =AA39 -> 19 | W43: =AA42 -> 18
H45: Total | J45: =J39+J42 -> 14 | Y45: Total | AA45: =AA39+AA42 -> 37
D46: =J39/J45 -> 0.42857143 | U46: =AA39/AA45 -> 0.51351351

Sheet Individual DF 1220_vs帝京
B2: vs | C2: ='Summary 1220_vs帝京'!O3 -> 帝京大学 | F2: Individual DF Stats | V2: 分析担当 | Z2: Tackle | AB2: 久留創・米倉杏
B4: Team Stats | E4: 総タックル | H4: =G34 -> 193 | J4: Defeat成功率 | M4: =(K34+T34)/G34 -> 0.051813472 | O4: タックル成功率 | R4: =SUM(K34:L34,T34:U34)/G34 -> 0.80310881 | U4: リアクション | X4: 1st | AA4: =SUM(O34:P34)/SUM(K34:L34) -> 0.69767442 | AB4: Assist | AE4: =SUM(X32:Y32)/SUM(T32:U32) -> 0.73333333
I6: 1st Tackle | N6: 1st Tackle Reaction | R6: Assist Tackle | W6: Assist Tackle Reaction | AA6: BD Works
D7: 出場時間 | E7: プレー総数 | F7: プレー換算値 | G7: タックル数 | H7: ％ | I7: 合計 | J7: ％ | K7: ◎ Defeat | L7: ○ 倒す | M7: × 失敗 | N7: % | O7: ファイト | P7: リロード | Q7: × | R7: 合計 | S7: ％ | T7: ◎ Defeat | U7: ○ 倒す | V7: × 失敗 | W7: % | X7: ファイト | Y7: リロード | Z7: × | AA7: 合計 | AB7: % | AC7: Jackal,Jerk | AD7: Pressure | AE7: BD Work × | AF7: 選手名
B8: 1 | C8: 湯浅大心 | D8: 77 | E8: =G8+AA8+'Individual AT 1220_vs帝京'!G8+'Individual AT 1220_vs帝京'!N8 -> 26 | F8: =IFERROR(E8/D8*80,"-") -> 27.012987 | G8: =I8+R8 -> 16 | H8: =IFERROR((K8+L8+T8+U8)/G8,"-") -> 0.6875 | I8: =SUM(K8:M8) -> 11 | J8: =IFERROR((K8+L8)/I8,"-") -> 0.63636364 | K8: 0 | L8: 7 | M8: 4 | N8: =IFERROR((O8+P8)/I8,"-") -> 0.45454545 | O8: 0 | P8: 5 | Q8: 2 | R8: =SUM(T8:V8) -> 5 | S8: =IFERROR((T8+U8)/R8,"-") -> 0.8 | T8: 0 | U8: 4 | V8: 1 | W8: =IFERROR((X8+Y8)/R8,"-") -> 0.6 | X8: 0 | Y8: 3 | Z8: 1 | AA8: 0 | AB8: =IFERROR((AC8+AD8)/AA8,"-") -> - | AC8: 2 | AD8: 0 | AE8: 1 | AF8: =C8 -> 湯浅大心
B9: 2 | C9: 前川陽来 | D9: 18 | E9: =G9+AA9+'Individual AT 1220_vs帝京'!G9+'Individual AT 1220_vs帝京'!N9 -> 8 | F9: =IFERROR(E9/D9*80,"-") -> 35.555556 | G9: =I9+R9 -> 7 | H9: =IFERROR((K9+L9+T9+U9)/G9,"-") -> 0.85714286 | I9: =SUM(K9:M9) -> 5 | J9: =IFERROR((K9+L9)/I9,"-") -> 0.8 | K9: 0 | L9: 4 | M9: 1 | N9: =IFERROR((O9+P9)/I9,"-") -> 0.4 | O9: 1 | P9: 1 | Q9: 2 | R9: =SUM(T9:V9) -> 2 | S9: =IFERROR((T9+U9)/R9,"-") -> 1 | T9: 0 | U9: 2 | V9: 0 | W9: =IFERROR((X9+Y9)/R9,"-") -> 0.5 | X9: 0 | Y9: 1 | Z9: 1 | AA9: =SUM(AC9:AE9) -> 0 | AB9: =IFERROR((AC9+AD9)/AA9,"-") -> - | AC9: 0 | AD9: 0 | AE9: 0 | AF9: =C9 -> 前川陽来
B10: 3 | C10: 茨木海斗 | D10: 81 | E10: =G10+AA10+'Individual AT 1220_vs帝京'!G10+'Individual AT 1220_vs帝京'!N10 -> 32 | F10: =IFERROR(E10/D10*80,"-") -> 31.604938 | G10: =I10+R10 -> 15 | H10: =IFERROR((K10+L10+T10+U10)/G10,"-") -> 0.93333333 | I10: =SUM(K10:M10) -> 6 | J10: =IFERROR((K10+L10)/I10,"-") -> 0.83333333 | K10: 2 | L10: 3 | M10: 1 | N10: =IFERROR((O10+P10)/I10,"-") -> 0.66666667 | O10: 3 | P10: 1 | Q10: 1 | R10: =SUM(T10:V10) -> 9 | S10: =IFERROR((T10+U10)/R10,"-") -> 1 | T10: 0 | U10: 9 | V10: 0 | W10: =IFERROR((X10+Y10)/R10,"-") -> 0.55555556 | X10: 5 | Y10: 0 | Z10: 4 | AA10: =SUM(AC10:AE10) -> 4 | AB10: =IFERROR((AC10+AD10)/AA10,"-") -> 0.75 | AC10: 1 | AD10: 2 | AE10: 1 | AF10: =C10 -> 茨木海斗
B11: 4 | C11: 磯部俊太朗 | D11: 81 | E11: =G11+AA11+'Individual AT 1220_vs帝京'!G11+'Individual AT 1220_vs帝京'!N11 -> 39 | F11: =IFERROR(E11/D11*80,"-") -> 38.518519 | G11: =I11+R11 -> 15 | H11: =IFERROR((K11+L11+T11+U11)/G11,"-") -> 0.73333333 | I11: =SUM(K11:M11) -> 8 | J11: =IFERROR((K11+L11)/I11,"-") -> 0.5 | K11: 0 | L11: 4 | M11: 4 | N11: =IFERROR((O11+P11)/I11,"-") -> 0.375 | O11: 0 | P11: 3 | Q11: 1 | R11: =SUM(T11:V11) -> 7 | S11: =IFERROR((T11+U11)/R11,"-") -> 1 | T11: 0 | U11: 7 | V11: 0 | W11: =IFERROR((X11+Y11)/R11,"-") -> 0.85714286 | X11: 3 | Y11: 3 | Z11: 1 | AA11: =SUM(AC11:AE11) -> 2 | AB11: =IFERROR((AC11+AD11)/AA11,"-") -> 0.5 | AC11: 1 | AD11: 0 | AE11: 1 | AF11: =C11 -> 磯部俊太朗
B12: 5 | C12: 白丸智乃祐 | D12: 81 | E12: =G12+AA12+'Individual AT 1220_vs帝京'!G12+'Individual AT 1220_vs帝京'!N12 -> 35 | F12: =IFERROR(E12/D12*80,"-") -> 34.567901 | G12: =I12+R12 -> 9 | H12: =IFERROR((K12+L12+T12+U12)/G12,"-") -> 0.88888889 | I12: =SUM(K12:M12) -> 5 | J12: =IFERROR((K12+L12)/I12,"-") -> 0.8 | K12: 0 | L12: 4 | M12: 1 | N12: =IFERROR((O12+P12)/I12,"-") -> 0.6 | O12: 0 | P12: 3 | Q12: 1 | R12: =SUM(T12:V12) -> 4 | S12: =IFERROR((T12+U12)/R12,"-") -> 1 | T12: 1 | U12: 3 | V12: 0 | W12: =IFERROR((X12+Y12)/R12,"-") -> 0.75 | X12: 2 | Y12: 1 | Z12: 1 | AA12: =SUM(AC12:AE12) -> 7 | AB12: =IFERROR((AC12+AD12)/AA12,"-") -> 0.71428571 | AC12: 1 | AD12: 4 | AE12: 2 | AF12: =C12 -> 白丸智乃祐
B13: 6 | C13: 茨木颯 | D13: 81 | E13: =G13+AA13+'Individual AT 1220_vs帝京'!G13+'Individual AT 1220_vs帝京'!N13 -> 30 | F13: =IFERROR(E13/D13*80,"-") -> 29.62963 | G13: =I13+R13 -> 6 | H13: =IFERROR((K13+L13+T13+U13)/G13,"-") -> 0.83333333 | I13: =SUM(K13:M13) -> 4 | J13: =IFERROR((K13+L13)/I13,"-") -> 0.75 | K13: 0 | L13: 3 | M13: 1 | N13: =IFERROR((O13+P13)/I13,"-") -> 0.25 | O13: 1 | P13: 0 | Q13: 2 | R13: =SUM(T13:V13) -> 2 | S13: =IFERROR((T13+U13)/R13,"-") -> 1 | T13: 0 | U13: 2 | V13: 0 | W13: =IFERROR((X13+Y13)/R13,"-") -> 0.5 | X13: 1 | Y13: 0 | Z13: 1 | AA13: =SUM(AC13:AE13) -> 4 | AB13: =IFERROR((AC13+AD13)/AA13,"-") -> 1 | AC13: 1 | AD13: 3 | AE13: 0 | AF13: =C13 -> 茨木颯
B14: 7 | C14: 中森真翔 | D14: 77 | E14: =G14+AA14+'Individual AT 1220_vs帝京'!G14+'Individual AT 1220_vs帝京'!N14 -> 16 | F14: =IFERROR(E14/D14*80,"-") -> 16.623377 | G14: =I14+R14 -> 10 | H14: =IFERROR((K14+L14+T14+U14)/G14,"-") -> 0.8 | I14: =SUM(K14:M14) -> 7 | J14: =IFERROR((K14+L14)/I14,"-") -> 0.71428571 | K14: 1 | L14: 4 | M14: 2 | N14: =IFERROR((O14+P14)/I14,"-") -> 0.42857143 | O14: 0 | P14: 3 | Q14: 2 | R14: =SUM(T14:V14) -> 3 | S14: =IFERROR((T14+U14)/R14,"-") -> 1 | T14: 0 | U14: 3 | V14: 0 | W14: =IFERROR((X14+Y14)/R14,"-") -> 0.66666667 | X14: 2 | Y14: 0 | Z14: 1 | AA14: =SUM(AC14:AE14) -> 2 | AB14: =IFERROR((AC14+AD14)/AA14,"-") -> 0.5 | AC14: 0 | AD14: 1 | AE14: 1 | AF14: =C14 -> 中森真翔
B15: 8 | C15: 大町尚生 | D15: 52 | E15: =G15+AA15+'Individual AT 1220_vs帝京'!G15+'Individual AT 1220_vs帝京'!N15 -> 21 | F15: =IFERROR(E15/D15*80,"-") -> 32.307692 | G15: =I15+R15 -> 11 | H15: =IFERROR((K15+L15+T15+U15)/G15,"-") -> 0.90909091 | I15: =SUM(K15:M15) -> 5 | J15: =IFERROR((K15+L15)/I15,"-") -> 0.8 | K15: 0 | L15: 4 | M15: 1 | N15: =IFERROR((O15+P15)/I15,"-") -> 0.6 | O15: 0 | P15: 3 | Q15: 1 | R15: =SUM(T15:V15) -> 6 | S15: =IFERROR((T15+U15)/R15,"-") -> 1 | T15: 0 | U15: 6 | V15: 0 | W15: =IFERROR((X15+Y15)/R15,"-") -> 1 | X15: 2 | Y15: 4 | Z15: 0 | AA15: =SUM(AC15:AE15) -> 4 | AB15: =IFERROR((AC15+AD15)/AA15,"-") -> 0.5 | AC15: 0 | AD15: 2 | AE15: 2 | AF15: =C15 -> 大町尚生
B16: 9 | C16: 高橋佑太朗 | D16: 6 | E16: =G16+AA16+'Individual AT 1220_vs帝京'!G16+'Individual AT 1220_vs帝京'!N16 -> 2 | F16: =IFERROR(E16/D16*80,"-") -> 26.666667 | G16: =I16+R16 -> 1 | H16: =IFERROR((K16+L16+T16+U16)/G16,"-") -> 1 | I16: =SUM(K16:M16) -> 1 | J16: =IFERROR((K16+L16)/I16,"-") -> 1 | K16: 0 | L16: 1 | M16: 0 | N16: =IFERROR((O16+P16)/I16,"-") -> 0 | O16: 0 | P16: 0 | Q16: 1 | R16: =SUM(T16:V16) -> 0 | S16: =IFERROR((T16+U16)/R16,"-") -> - | T16: 0 | U16: 0 | V16: 0 | W16: =IFERROR((X16+Y16)/R16,"-") -> - | X16: 0 | Y16: 0 | Z16: 0 | AA16: =SUM(AC16:AE16) -> 1 | AB16: =IFERROR((AC16+AD16)/AA16,"-") -> 0 | AC16: 0 | AD16: 0 | AE16: 1 | AF16: =C16 -> 高橋佑太朗
B17: 10 | C17: 楢本幹志朗 | D17: 81 | E17: =G17+AA17+'Individual AT 1220_vs帝京'!G17+'Individual AT 1220_vs帝京'!N17 -> 4 | F17: =IFERROR(E17/D17*80,"-") -> 3.9506173 | G17: =I17+R17 -> 1 | H17: =IFERROR((K17+L17+T17+U17)/G17,"-") -> 1 | I17: =SUM(K17:M17) -> 1 | J17: =IFERROR((K17+L17)/I17,"-") -> 1 | K17: 0 | L17: 1 | M17: 0 | N17: =IFERROR((O17+P17)/I17,"-") -> 0 | O17: 0 | P17: 0 | Q17: 1 | R17: =SUM(T17:V17) -> 0 | S17: =IFERROR((T17+U17)/R17,"-") -> - | T17: 0 | U17: 0 | V17: 0 | W17: =IFERROR((X17+Y17)/R17,"-") -> - | X17: 0 | Y17: 0 | Z17: 0 | AA17: =SUM(AC17:AE17) -> 1 | AB17: =IFERROR((AC17+AD17)/AA17,"-") -> 0 | AC17: 0 | AD17: 0 | AE17: 1 | AF17: =C17 -> 楢本幹志朗
B18: 11 | C18: 内田慎之甫 | D18: 81 | E18: =G18+AA18+'Individual AT 1220_vs帝京'!G18+'Individual AT 1220_vs帝京'!N18 -> 11 | F18: =IFERROR(E18/D18*80,"-") -> 10.864198 | G18: =I18+R18 -> 9 | H18: =IFERROR((K18+L18+T18+U18)/G18,"-") -> 0.77777778 | I18: =SUM(K18:M18) -> 8 | J18: =IFERROR((K18+L18)/I18,"-") -> 0.75 | K18: 1 | L18: 5 | M18: 2 | N18: =IFERROR((O18+P18)/I18,"-") -> 0.625 | O18: 0 | P18: 5 | Q18: 1 | R18: =SUM(T18:V18) -> 1 | S18: =IFERROR((T18+U18)/R18,"-") -> 1 | T18: 0 | U18: 1 | V18: 0 | W18: =IFERROR((X18+Y18)/R18,"-") -> 1 | X18: 1 | Y18: 0 | Z18: 0 | AA18: =SUM(AC18:AE18) -> 0 | AB18: =IFERROR((AC18+AD18)/AA18,"-") -> - | AC18: 0 | AD18: 0 | AE18: 0 | AF18: =C18 -> 内田慎之甫
B19: 12 | C19: 大内田陽冬 | D19: 70 | E19: =G19+AA19+'Individual AT 1220_vs帝京'!G19+'Individual AT 1220_vs帝京'!N19 -> 21 | F19: =IFERROR(E19/D19*80,"-") -> 24 | G19: =I19+R19 -> 14 | H19: =IFERROR((K19+L19+T19+U19)/G19,"-") -> 0.92857143 | I19: =SUM(K19:M19) -> 5 | J19: =IFERROR((K19+L19)/I19,"-") -> 0.8 | K19: 0 | L19: 4 | M19: 1 | N19: =IFERROR((O19+P19)/I19,"-") -> 0.6 | O19: 2 | P19: 1 | Q19: 1 | R19: =SUM(T19:V19) -> 9 | S19: =IFERROR((T19+U19)/R19,"-") -> 1 | T19: 1 | U19: 8 | V19: 0 | W19: =IFERROR((X19+Y19)/R19,"-") -> 0.66666667 | X19: 3 | Y19: 3 | Z19: 3 | AA19: =SUM(AC19:AE19) -> 1 | AB19: =IFERROR((AC19+AD19)/AA19,"-") -> 1 | AC19: 1 | AD19: 0 | AE19: 0 | AF19: =C19 -> 大内田陽冬
B20: 13 | C20: 東島和哉 | D20: 81 | E20: =G20+AA20+'Individual AT 1220_vs帝京'!G20+'Individual AT 1220_vs帝京'!N20 -> 27 | F20: =IFERROR(E20/D20*80,"-") -> 26.666667 | G20: =I20+R20 -> 18 | H20: =IFERROR((K20+L20+T20+U20)/G20,"-") -> 0.66666667 | I20: =SUM(K20:M20) -> 13 | J20: =IFERROR((K20+L20)/I20,"-") -> 0.61538462 | K20: 1 | L20: 7 | M20: 5 | N20: =IFERROR((O20+P20)/I20,"-") -> 0.46153846 | O20: 0 | P20: 6 | Q20: 2 | R20: =SUM(T20:V20) -> 5 | S20: =IFERROR((T20+U20)/R20,"-") -> 0.8 | T20: 0 | U20: 4 | V20: 1 | W20: =IFERROR((X20+Y20)/R20,"-") -> 0.8 | X20: 1 | Y20: 3 | Z20: 0 | AA20: =SUM(AC20:AE20) -> 0 | AB20: =IFERROR((AC20+AD20)/AA20,"-") -> - | AC20: 0 | AD20: 0 | AE20: 0 | AF20: =C20 -> 東島和哉
... B30: 23 | C30: 林勇太 | D30: 0 | E30: =G30+AA30+'Individual AT 1220_vs帝京'!G30+'Individual AT 1220_vs帝京'!N30 -> 0 | F30: =IFERROR(E30/D30*80,"-") -> - | G30: =I30+R30 -> 0 | H30: =IFERROR((K30+L30+T30+U30)/G30,"-") -> - | I30: =SUM(K30:M30) -> 0 | J30: =IFERROR((K30+L30)/I30,"-") -> - | K30: 0 | L30: 0 | M30: 0 | N30: =IFERROR((O30+P30)/I30,"-") -> - | O30: 0 | P30: 0 | Q30: 0 | R30: =SUM(T30:V30) -> 0 | S30: =IFERROR((T30+U30)/R30,"-") -> - | T30: 0 | U30: 0 | V30: 0 | W30: =IFERROR((X30+Y30)/R30,"-") -> - | X30: 0 | Y30: 0 | Z30: 0 | AA30: =SUM(AC30:AE30) -> 0 | AB30: =IFERROR((AC30+AD30)/AA30,"-") -> - | AC30: 0 | AD30: 0 | AE30: 0 | AF30: =C30 -> 林勇太
B32: FW Total | G32: =SUM(G8:G15,G23:G27) -> 110 | I32: =SUM(I8:I15,I23:I27) -> 64 | J32: =SUM(K32:L32)/I32 -> 0.75 | K32: =SUM(K8:K15,K23:K27) -> 3 | L32: =SUM(L8:L15,L23:L27) -> 45 | M32: =SUM(M8:M15,M23:M27) -> 16 | N32: =SUM(O32:P32)/I32 -> 0.5 | O32: =SUM(O8:O15,O23:O27) -> 8 | P32: =SUM(P8:P15,P23:P27) -> 24 | Q32: =SUM(Q8:Q15,Q23:Q27) -> 16 | R32: =SUM(R8:R15,R23:R27) -> 46 | S32: =SUM(T32:U32)/R32 -> 0.97826087 | T32: =SUM(T8:T15,T23:T27) -> 3 | U32: =SUM(U8:U15,U23:U27) -> 42 | V32: =SUM(V8:V15,V23:V27) -> 1 | W32: =SUM(X32:Y32)/SUM(X32:Z32) -> 0.73333333 | X32: =SUM(X8:X15,X23:X27) -> 18 | Y32: =SUM(Y8:Y15,Y23:Y27) -> 15 | Z32: =SUM(Z8:Z15,Z23:Z27) -> 12 | AA32: =SUM(AA8:AA15,AA23:AA27) -> 29 | AB32: =SUM(AC32:AD32)/SUM(AC32:AE32) -> 0.6875 | AC32: =SUM(AC8:AC15,AC23:AC27) -> 8 | AD32: =SUM(AD8:AD15,AD23:AD27) -> 14 | AE32: =SUM(AE8:AE15,AE23:AE27) -> 10 | AF32: FW Total
B33: BK Total | G33: =SUM(G16:G22,G28:G30) -> 83 | I33: =SUM(I16:I22,I28:I30) -> 56 | J33: =SUM(K33:L33)/I33 -> 0.67857143 | K33: =SUM(K16:K22,K28:K30) -> 2 | L33: =SUM(L16:L22,L28:L30) -> 36 | M33: =SUM(M16:M22,M28:M30) -> 18 | N33: =SUM(O33:P33)/I33 -> 0.5 | O33: =SUM(O16:O22,O28:O30) -> 4 | P33: =SUM(P16:P22,P28:P30) -> 24 | Q33: =SUM(Q16:Q22,Q28:Q30) -> 10 | R33: =SUM(R16:R22,R28:R30) -> 27 | S33: =SUM(T33:U33)/R33 -> 0.88888889 | T33: =SUM(T16:T22,T28:T30) -> 2 | U33: =SUM(U16:U22,U28:U30) -> 22 | V33: =SUM(V16:V22,V28:V30) -> 3 | W33: =SUM(X33:Y33)/SUM(X33:Z33) -> 0.875 | X33: =SUM(X16:X22,X28:X30) -> 10 | Y33: =SUM(Y16:Y22,Y28:Y30) -> 11 | Z33: =SUM(Z16:Z22,Z28:Z30) -> 3 | AA33: =SUM(AA16:AA22,AA28:AA30) -> 11 | AB33: =SUM(AC33:AD33)/SUM(AC33:AE33) -> 0.63636364 | AC33: =SUM(AC16:AC22,AC28:AC30) -> 4 | AD33: =SUM(AD16:AD22,AD28:AD30) -> 3 | AE33: =SUM(AE16:AE22,AE28:AE30) -> 4 | AF33: BK Total
B34: Team Total | G34: =SUM(G8:G30) -> 193 | I34: =SUM(I8:I30) -> 120 | J34: =SUM(K34:L34)/I34 -> 0.71666667 | K34: =SUM(K8:K30) -> 5 | L34: =SUM(L8:L30) -> 81 | M34: =SUM(M8:M30) -> 34 | N34: =SUM(O34:P34)/I34 -> 0.5 | O34: =SUM(O8:O30) -> 12 | P34: =SUM(P8:P30) -> 48 | Q34: =SUM(Q8:Q30) -> 26 | R34: =SUM(R8:R30) -> 73 | S34: =SUM(T34:U34)/R34 -> 0.94520548 | T34: =SUM(T8:T30) -> 5 | U34: =SUM(U8:U30) -> 64 | V34: =SUM(V8:V30) -> 4 | W34: =SUM(X34:Y34)/SUM(X34:Z34) -> 0.7826087 | X34: =SUM(X8:X30) -> 28 | Y34: =SUM(Y8:Y30) -> 26 | Z34: =SUM(Z8:Z30) -> 15 | AA34: =SUM(AA8:AA30) -> 40 | AB34: =SUM(AC34:AD34)/SUM(AC34:AE34) -> 0.6744186 | AC34: =SUM(AC8:AC30) -> 12 | AD34: =SUM(AD8:AD30) -> 17 | AE34: =SUM(AE8:AE30) -> 14 | AF34: Team Total
B35: Team Average | G35: =AVERAGE(G8:G30) -> 8.3913043 | I35: =AVERAGE(I8:I30) -> 5.2173913 | K35: =AVERAGE(K8:K30) -> 0.2173913 | L35: =AVERAGE(L8:L30) -> 3.5217391 | M35: =AVERAGE(M8:M30) -> 1.4782609 | O35: =AVERAGE(O8:O30) -> 0.52173913 | P35: =AVERAGE(P8:P30) -> 2.0869565 | Q35: =AVERAGE(Q8:Q30) -> 1.1304348 | R35: =AVERAGE(R8:R30) -> 3.173913 | T35: =AVERAGE(T8:T30) -> 0.2173913 | U35: =AVERAGE(U8:U30) -> 2.7826087 | V35: =AVERAGE(V8:V30) -> 0.17391304 | X35: =AVERAGE(X8:X30) -> 1.2173913 | Y35: =AVERAGE(Y8:Y30) -> 1.1304348 | Z35: =AVERAGE(Z8:Z30) -> 0.65217391 | AA35: =AVERAGE(AA8:AA30) -> 1.7391304 | AC35: =AVERAGE(AC8:AC30) -> 0.52173913 | AD35: =AVERAGE(AD8:AD30) -> 0.73913043 | AE35: =AVERAGE(AE8:AE30) -> 0.60869565 | AF35: Team Average

Sheet Individual AT 1220_vs帝京
B2: vs | C2: ='Summary 1220_vs帝京'!O3 -> 帝京大学 | F2: Individual AT Stats | O2: 分析担当 | S2: 表 | Y2: B2,3 | AA2: 米倉杏
B4: Team Stats | E4: Body Ball Control | J4: =H34 -> 0.87037037 | N4: Support | R4: =O34 -> 0.94957983 | U4: B3 | X4: =T34 -> 0.86029412 | Z4: B2 | AC4: =Z34 -> 0.66423358
G6: Carrier Contact | N6: Support | S6: B3 | Y6: B2
D7: 出場時間 | E7: プレー総数 | F7: プレー換算値 | G7: 合計 | H7: Good/Stay ％ | I7: BB% | J7: Gain◎ | K7: Stay○ | L7: 後退△ | M7: Lost× | N7: 合計 | O7: ％ | P7: EXELLENT◎ | Q7: GOOD○ | R7: BAD× | S7: 合計 | T7: ％ | U7: Carrier○ | V7: Carrier× | W7: Support○ | X7: Support× | Y7: 合計 | Z7: ％ | AA7: Carrier○ | AB7: Carrier× | AC7: Support○ | AD7: Support× | AE7: 選手名
B8: 1 | C8: ='Individual DF 1220_vs帝京'!C8 -> 湯浅大心 | D8: ='Individual DF 1220_vs帝京'!D8 -> 77 | E8: ='Individual DF 1220_vs帝京'!E8 -> 26 | F8: ='Individual DF 1220_vs帝京'!F8 -> 27.012987 | G8: =SUM(J8:M8) -> 6 | H8: =IFERROR((J8+K8)/SUM(J8:M8),"-") -> 1 | I8: =IFERROR(SUM(J8:L8)/SUM(J8:M8),"-") -> 1 | J8: 0 | K8: 6 | L8: 0 | M8: 0 | N8: =SUM(P8:R8) -> 4 | O8: =IFERROR((P8+Q8)/N8,"-") -> 0.75 | P8: 0 | Q8: 3 | R8: 1 | S8: =SUM(U8:X8) -> 9 | T8: =IFERROR((U8+W8)/S8,"-") -> 0.44444444 | U8: 1 | V8: 5 | W8: 3 | X8: 0 | Y8: =SUM(AA8:AD8) -> 9 | Z8: =IFERROR((AA8+AC8)/Y8,"-") -> 0.44444444 | AA8: 1 | AB8: 5 | AC8: 3 | AD8: 0 | AE8: =C8 -> 湯浅大心
B9: 2 | C9: ='Individual DF 1220_vs帝京'!C9 -> 前川陽来 | D9: ='Individual DF 1220_vs帝京'!D9 -> 18 | E9: ='Individual DF 1220_vs帝京'!E9 -> 8 | F9: ='Individual DF 1220_vs帝京'!F9 -> 35.555556 | G9: =SUM(J9:M9) -> 0 | H9: =IFERROR((J9+K9)/SUM(J9:M9),"-") -> - | I9: =IFERROR(SUM(J9:L9)/SUM(J9:M9),"-") -> - | J9: 0 | K9: 0 | L9: 0 | M9: 0 | N9: =SUM(P9:R9) -> 1 | O9: =IFERROR((P9+Q9)/N9,"-") -> 1 | P9: 0 | Q9: 1 | R9: 0 | S9: =SUM(U9:X9) -> 1 | T9: =IFERROR((U9+W9)/S9,"-") -> 1 | U9: 0 | V9: 0 | W9: 1 | X9: 0 | Y9: =SUM(AA9:AD9) -> 1 | Z9: =IFERROR((AA9+AC9)/Y9,"-") -> 1 | AA9: 0 | AB9: 0 | AC9: 1 | AD9: 0 | AE9: =C9 -> 前川陽来
B10: 3 | C10: ='Individual DF 1220_vs帝京'!C10 -> 茨木海斗 | D10: ='Individual DF 1220_vs帝京'!D10 -> 81 | E10: ='Individual DF 1220_vs帝京'!E10 -> 32 | F10: ='Individual DF 1220_vs帝京'!F10 -> 31.604938 | G10: =SUM(J10:M10) -> 4 | H10: =IFERROR((J10+K10)/SUM(J10:M10),"-") -> 1 | I10: =IFERROR(SUM(J10:L10)/SUM(J10:M10),"-") -> 1 | J10: 0 | K10: 4 | L10: 0 | M10: 0 | N10: =SUM(P10:R10) -> 9 | O10: =IFERROR((P10+Q10)/N10,"-") -> 1 | P10: 0 | Q10: 9 | R10: 0 | S10: =SUM(U10:X10) -> 10 | T10: =IFERROR((U10+W10)/S10,"-") -> 0.6 | U10: 0 | V10: 4 | W10: 6 | X10: 0 | Y10: =SUM(AA10:AD10) -> 10 | Z10: =IFERROR((AA10+AC10)/Y10,"-") -> 0.6 | AA10: 0 | AB10: 4 | AC10: 6 | AD10: 0 | AE10: =C10 -> 茨木海斗
B11: 4 | C11: ='Individual DF 1220_vs帝京'!C11 -> 磯部俊太朗 | D11: ='Individual DF 1220_vs帝京'!D11 -> 81 | E11: ='Individual DF 1220_vs帝京'!E11 -> 39 | F11: ='Individual DF 1220_vs帝京'!F11 -> 38.518519 | G11: =SUM(J11:M11) -> 9 | H11: =IFERROR((J11+K11)/SUM(J11:M11),"-") -> 1 | I11: =IFERROR(SUM(J11:L11)/SUM(J11:M11),"-") -> 1 | J11: 2 | K11: 7 | L11: 0 | M11: 0 | N11: =SUM(P11:R11) -> 13 | O11: =IFERROR((P11+Q11)/N11,"-") -> 0.92307692 | P11: 0 | Q11: 12 | R11: 1 | S11: =SUM(U11:X11) -> 19 | T11: =IFERROR((U11+W11)/S11,"-") -> 0.89473684 | U11: 7 | V11: 1 | W11: 10 | X11: 1 | Y11: =SUM(AA11:AD11) -> 19 | Z11: =IFERROR((AA11+AC11)/Y11,"-") -> 0.63157895 | AA11: 5 | AB11: 3 | AC11: 7 | AD11: 4 | AE11: =C11 -> 磯部俊太朗
B12: 5 | C12: ='Individual DF 1220_vs帝京'!C12 -> 白丸智乃祐 | D12: ='Individual DF 1220_vs帝京'!D12 -> 81 | E12: ='Individual DF 1220_vs帝京'!E12 -> 35 | F12: ='Individual DF 1220_vs帝京'!F12 -> 34.567901 | G12: =SUM(J12:M12) -> 1 | H12: =IFERROR((J12+K12)/SUM(J12:M12),"-") -> 1 | I12: =IFERROR(SUM(J12:L12)/SUM(J12:M12),"-") -> 1 | J12: 0 | K12: 1 | L12: 0 | M12: 0 | N12: =SUM(P12:R12) -> 18 | O12: =IFERROR((P12+Q12)/N12,"-") -> 0.94444444 | P12: 0 | Q12: 17 | R12: 1 | S12: =SUM(U12:X12) -> 15 | T12: =IFERROR((U12+W12)/S12,"-") -> 0.93333333 | U12: 0 | V12: 1 | W12: 14 | X12: 0 | Y12: =SUM(AA12:AD12) -> 15 | Z12: =IFERROR((AA12+AC12)/Y12,"-") -> 0.73333333 | AA12: 0 | AB12: 1 | AC12: 11 | AD12: 3 | AE12: =C12 -> 白丸智乃祐
B13: 6 | C13: ='Individual DF 1220_vs帝京'!C13 -> 茨木颯 | D13: ='Individual DF 1220_vs帝京'!D13 -> 81 | E13: ='Individual DF 1220_vs帝京'!E13 -> 30 | F13: ='Individual DF 1220_vs帝京'!F13 -> 29.62963 | G13: =SUM(J13:M13) -> 2 | H13: =IFERROR((J13+K13)/SUM(J13:M13),"-") -> 1 | I13: =IFERROR(SUM(J13:L13)/SUM(J13:M13),"-") -> 1 | J13: 0 | K13: 2 | L13: 0 | M13: 0 | N13: =SUM(P13:R13) -> 18 | O13: =IFERROR((P13+Q13)/N13,"-") -> 0.88888889 | P13: 0 | Q13: 16 | R13: 2 | S13: =SUM(U13:X13) -> 15 | T13: =IFERROR((U13+W13)/S13,"-") -> 0.93333333 | U13: 1 | V13: 1 | W13: 13 | X13: 0 | Y13: =SUM(AA13:AD13) -> 15 | Z13: =IFERROR((AA13+AC13)/Y13,"-") -> 0.73333333 | AA13: 0 | AB13: 2 | AC13: 11 | AD13: 2 | AE13: =C13 -> 茨木颯
B14: 7 | C14: ='Individual DF 1220_vs帝京'!C14 -> 中森真翔 | D14: ='Individual DF 1220_vs帝京'!D14 -> 77 | E14: ='Individual DF 1220_vs帝京'!E14 -> 16 | F14: ='Individual DF 1220_vs帝京'!F14 -> 16.623377 | G14: =SUM(J14:M14) -> 1 | H14: =IFERROR((J14+K14)/SUM(J14:M14),"-") -> 1 | I14: =IFERROR(SUM(J14:L14)/SUM(J14:M14),"-") -> 1 | J14: 0 | K14: 1 | L14: 0 | M14: 0 | N14: =SUM(P14:R14) -> 3 | O14: =IFERROR((P14+Q14)/N14,"-") -> 1 | P14: 0 | Q14: 3 | R14: 0 | S14: =SUM(U14:X14) -> 5 | T14: =IFERROR((U14+W14)/S14,"-") -> 1 | U14: 2 | V14: 0 | W14: 3 | X14: 0 | Y14: =SUM(AA14:AD14) -> 5 | Z14: =IFERROR((AA14+AC14)/Y14,"-") -> 1 | AA14: 2 | AB14: 0 | AC14: 3 | AD14: 0 | AE14: =C14 -> 中森真翔
B15: 8 | C15: ='Individual DF 1220_vs帝京'!C15 -> 大町尚生 | D15: ='Individual DF 1220_vs帝京'!D15 -> 52 | E15: ='Individual DF 1220_vs帝京'!E15 -> 21 | F15: ='Individual DF 1220_vs帝京'!F15 -> 32.307692 | G15: =SUM(J15:M15) -> 1 | H15: =IFERROR((J15+K15)/SUM(J15:M15),"-") -> 1 | I15: =IFERROR(SUM(J15:L15)/SUM(J15:M15),"-") -> 1 | J15: 0 | K15: 1 | L15: 0 | M15: 0 | N15: =SUM(P15:R15) -> 5 | O15: =IFERROR((P15+Q15)/N15,"-") -> 1 | P15: 0 | Q15: 5 | R15: 0 | S15: =SUM(U15:X15) -> 6 | T15: =IFERROR((U15+W15)/S15,"-") -> 1 | U15: 1 | V15: 0 | W15: 5 | X15: 0 | Y15: =SUM(AA15:AD15) -> 6 | Z15: =IFERROR((AA15+AC15)/Y15,"-") -> 0.83333333 | AA15: 1 | AB15: 0 | AC15: 4 | AD15: 1 | AE15: =C15 -> 大町尚生
B16: 9 | C16: ='Individual DF 1220_vs帝京'!C16 -> 高橋佑太朗 | D16: ='Individual DF 1220_vs帝京'!D16 -> 6 | E16: ='Individual DF 1220_vs帝京'!E16 -> 2 | F16: ='Individual DF 1220_vs帝京'!F16 -> 26.666667 | G16: =SUM(J16:M16) -> 0 | H16: =IFERROR((J16+K16)/SUM(J16:M16),"-") -> - | I16: =IFERROR(SUM(J16:L16)/SUM(J16:M16),"-") -> - | J16: 0 | K16: 0 | L16: 0 | M16: 0 | N16: =SUM(P16:R16) -> 0 | O16: =IFERROR((P16+Q16)/N16,"-") -> - | P16: 0 | Q16: 0 | R16: 0 | S16: =SUM(U16:X16) -> 0 | T16: =IFERROR((U16+W16)/S16,"-") -> - | U16: 0 | V16: 0 | W16: 0 | X16: 0 | Y16: =SUM(AA16:AD16) -> 0 | Z16: =IFERROR((AA16+AC16)/Y16,"-") -> - | AA16: 0 | AB16: 0 | AC16: 0 | AD16: 0 | AE16: =C16 -> 高橋佑太朗
B17: 10 | C17: ='Individual DF 1220_vs帝京'!C17 -> 楢本幹志朗 | D17: ='Individual DF 1220_vs帝京'!D17 -> 81 | E17: ='Individual DF 1220_vs帝京'!E17 -> 4 | F17: ='Individual DF 1220_vs帝京'!F17 -> 3.9506173 | G17: =SUM(J17:M17) -> 1 | H17: =IFERROR((J17+K17)/SUM(J17:M17),"-") -> 1 | I17: =IFERROR(SUM(J17:L17)/SUM(J17:M17),"-") -> 1 | J17: 0 | K17: 1 | L17: 0 | M17: 0 | N17: =SUM(P17:R17) -> 1 | O17: =IFERROR((P17+Q17)/N17,"-") -> 1 | P17: 0 | Q17: 1 | R17: 0 | S17: =SUM(U17:X17) -> 1 | T17: =IFERROR((U17+W17)/S17,"-") -> 1 | U17: 1 | V17: 0 | W17: 0 | X17: 0 | Y17: =SUM(AA17:AD17) -> 1 | Z17: =IFERROR((AA17+AC17)/Y17,"-") -> 1 | AA17: 1 | AB17: 0 | AC17: 0 | AD17: 0 | AE17: =C17 -> 楢本幹志朗
B18: 11 | C18: ='Individual DF 1220_vs帝京'!C18 -> 内田慎之甫 | D18: ='Individual DF 1220_vs帝京'!D18 -> 81 | E18: ='Individual DF 1220_vs帝京'!E18 -> 11 | F18: ='Individual DF 1220_vs帝京'!F18 -> 10.864198 | G18: =SUM(J18:M18) -> 0 | H18: =IFERROR((J18+K18)/SUM(J18:M18),"-") -> - | I18: =IFERROR(SUM(J18:L18)/SUM(J18:M18),"-") -> - | J18: 0 | K18: 0 | L18: 0 | M18: 0 | N18: =SUM(P18:R18) -> 2 | O18: =IFERROR((P18+Q18)/N18,"-") -> 1 | P18: 0 | Q18: 2 | R18: 0 | S18: =SUM(U18:X18) -> 1 | T18: =IFERROR((U18+W18)/S18,"-") -> 1 | U18: 0 | V18: 0 | W18: 1 | X18: 0 | Y18: =SUM(AA18:AD18) -> 1 | Z18: =IFERROR((AA18+AC18)/Y18,"-") -> 1 | AA18: 0 | AB18: 0 | AC18: 1 | AD18: 0 | AE18: =C18 -> 内田慎之甫
B19: 12 | C19: ='Individual DF 1220_vs帝京'!C19 -> 大内田陽冬 | D19: ='Individual DF 1220_vs帝京'!D19 -> 70 | E19: ='Individual DF 1220_vs帝京'!E19 -> 21 | F19: ='Individual DF 1220_vs帝京'!F19 -> 24 | G19: =SUM(J19:M19) -> 3 | H19: =IFERROR((J19+K19)/SUM(J19:M19),"-") -> 0.66666667 | I19: =IFERROR(SUM(J19:L19)/SUM(J19:M19),"-") -> 0.66666667 | J19: 1 | K19: 1 | L19: 0 | M19: 1 | N19: =SUM(P19:R19) -> 3 | O19: =IFERROR((P19+Q19)/N19,"-") -> 0.66666667 | P19: 0 | Q19: 2 | R19: 1 | S19: =SUM(U19:X19) -> 3 | T19: =IFERROR((U19+W19)/S19,"-") -> 1 | U19: 2 | V19: 0 | W19: 1 | X19: 0 | Y19: =SUM(AA19:AD19) -> 3 | Z19: =IFERROR((AA19+AC19)/Y19,"-") -> 0.33333333 | AA19: 0 | AB19: 2 | AC19: 1 | AD19: 0 | AE19: =C19 -> 大内田陽冬
... B30: 23 | C30: ='Individual DF 1220_vs帝京'!C30 -> 林勇太 | D30: ='Individual DF 1220_vs帝京'!D30 -> 0 | E30: ='Individual DF 1220_vs帝京'!E30 -> 0 | F30: ='Individual DF 1220_vs帝京'!F30 -> - | G30: =SUM(J30:M30) -> 0 | H30: =IFERROR((J30+K30)/SUM(J30:M30),"-") -> - | I30: =IFERROR(SUM(J30:L30)/SUM(J30:M30),"-") -> - | J30: 0 | K30: 0 | L30: 0 | M30: 0 | N30: =SUM(P30:R30) -> 0 | O30: =IFERROR((P30+Q30)/N30,"-") -> - | P30: 0 | Q30: 0 | R30: 0 | S30: =SUM(U30:X30) -> 0 | T30: =IFERROR((U30+W30)/S30,"-") -> - | U30: 0 | V30: 0 | W30: 0 | X30: 0 | Y30: =SUM(AA30:AD30) -> 0 | Z30: =IFERROR((AA30+AC30)/Y30,"-") -> - | AA30: 0 | AB30: 0 | AC30: 0 | AD30: 0 | AE30: =C30 -> 林勇太
B32: FW Total | G32: =SUM(G8:G15,G23:G27) -> 38 | H32: =SUM(J32:K32)/G32 -> 0.97368421 | I32: =SUM(J32:L32)/G32 -> 0.97368421 | J32: =SUM(J8:J15,J23:J27) -> 3 | K32: =SUM(K8:K15,K23:K27) -> 34 | L32: =SUM(L8:L15,L23:L27) -> 0 | M32: =SUM(M8:M15,M23:M27) -> 1 | N32: =SUM(N8:N15,N23:N27) -> 102 | O32: =IFERROR((P32+Q32)/N32,"-") -> 0.95098039 | P32: =SUM(P8:P15,P23:P27) -> 1 | Q32: =SUM(Q8:Q15,Q23:Q27) -> 96 | R32: =SUM(R8:R15,R23:R27) -> 5 | S32: =SUM(S8:S15,S23:S27) -> 118 | T32: =(U32+W32)/S32 -> 0.84745763 | U32: =SUM(U8:U15,U23:U27) -> 21 | V32: =SUM(V8:V15,V23:V27) -> 16 | W32: =SUM(W8:W15,W23:W27) -> 79 | X32: =SUM(X8:X15,X23:X27) -> 2 | Y32: =SUM(Y8:Y15,Y23:Y27) -> 119 | Z32: =(AA32+AC32)/Y32 -> 0.67226891 | AA32: =SUM(AA8:AA15,AA23:AA27) -> 12 | AB32: =SUM(AB8:AB15,AB23:AB27) -> 25 | AC32: =SUM(AC8:AC15,AC23:AC27) -> 68 | AD32: =SUM(AD8:AD15,AD23:AD27) -> 14 | AE32: FW Total
B33: BK Total | G33: =SUM(G16:G22,G28:G30) -> 16 | H33: =SUM(J33:K33)/G33 -> 0.625 | I33: =SUM(J33:L33)/G33 -> 0.75 | J33: =SUM(J16:J22,J28:J30) -> 3 | K33: =SUM(K16:K22,K28:K30) -> 7 | L33: =SUM(L16:L22,L28:L30) -> 2 | M33: =SUM(M16:M22,M28:M30) -> 4 | N33: =SUM(N16:N22,N28:N30) -> 17 | O33: =IFERROR((P33+Q33)/N33,"-") -> 0.94117647 | P33: =SUM(P16:P22,P28:P30) -> 0 | Q33: =SUM(Q16:Q22,Q28:Q30) -> 16 | R33: =SUM(R16:R22,R28:R30) -> 1 | S33: =SUM(S16:S22,S28:S30) -> 18 | T33: =(U33+W33)/S33 -> 0.94444444 | U33: =SUM(U16:U22,U28:U30) -> 8 | V33: =SUM(V16:V22,V28:V30) -> 1 | W33: =SUM(W16:W22,W28:W30) -> 9 | X33: =SUM(X16:X22,X28:X30) -> 0 | Y33: =SUM(Y16:Y22,Y28:Y30) -> 18 | Z33: =(AA33+AC33)/Y33 -> 0.61111111 | AA33: =SUM(AA16:AA22,AA28:AA30) -> 2 | AB33: =SUM(AB16:AB22,AB28:AB30) -> 7 | AC33: =SUM(AC16:AC22,AC28:AC30) -> 9 | AD33: =SUM(AD16:AD22,AD28:AD30) -> 0 | AE33: BK Total
B34: Team Total | G34: =SUM(G8:G30) -> 54 | H34: =SUM(J34:K34)/G34 -> 0.87037037 | I34: =SUM(J34:L34)/G34 -> 0.90740741 | J34: =SUM(J8:J30) -> 6 | K34: =SUM(K8:K30) -> 41 | L34: =SUM(L8:L30) -> 2 | M34: =SUM(M8:M30) -> 5 | N34: =SUM(N8:N30) -> 119 | O34: =IFERROR((P34+Q34)/N34,"-") -> 0.94957983 | P34: =SUM(P8:P30) -> 1 | Q34: =SUM(Q8:Q30) -> 112 | R34: =SUM(R8:R30) -> 6 | S34: =SUM(S8:S30) -> 136 | T34: =(U34+W34)/S34 -> 0.86029412 | U34: =SUM(U8:U30) -> 29 | V34: =SUM(V8:V30) -> 17 | W34: =SUM(W8:W30) -> 88 | X34: =SUM(X8:X30) -> 2 | Y34: =SUM(Y8:Y30) -> 137 | Z34: =(AA34+AC34)/Y34 -> 0.66423358 | AA34: =SUM(AA8:AA30) -> 14 | AB34: =SUM(AB8:AB30) -> 32 | AC34: =SUM(AC8:AC30) -> 77 | AD34: =SUM(AD8:AD30) -> 14 | AE34: Team Total
B35: Team Average | G35: =AVERAGE(G8:G30) -> 2.3478261 | J35: =AVERAGE(J8:J30) -> 0.26086957 | K35: =AVERAGE(K8:K30) -> 1.7826087 | L35: =AVERAGE(L8:L30) -> 0.086956522 | M35: =AVERAGE(M8:M30) -> 0.2173913 | P35: =AVERAGE(P8:P30) -> 0.043478261 | Q35: =AVERAGE(Q8:Q30) -> 4.8695652 | R35: =AVERAGE(R8:R30) -> 0.26086957 | S35: =AVERAGE(S8:S30) -> 5.9130435 | U35: =AVERAGE(U8:U30) -> 1.2608696 | V35: =AVERAGE(V8:V30) -> 0.73913043 | W35: =AVERAGE(W8:W30) -> 3.826087 | X35: =AVERAGE(X8:X30) -> 0.086956522 | Y35: =AVERAGE(Y8:Y30) -> 5.9565217 | AA35: =AVERAGE(AA8:AA30) -> 0.60869565 | AB35: =AVERAGE(AB8:AB30) -> 1.3913043 | AC35: =AVERAGE(AC8:AC30) -> 3.3478261 | AD35: =AVERAGE(AD8:AD30) -> 0.60869565 | AE35: Team Average

Sheet Set 1220_vs帝京
A1: VS | B1: ='Summary 1220_vs帝京'!O3 -> 帝京大学 | L1: 試合会場 | N1: 秩父宮ラグビー場 | O1: 天候・G状況 曇り・スリッピー | P1: 分析担当 小澤
A3: Set Play | L3: Penalty
A4: 筑波 | C4: 総数 | D4: 獲得率 | E4: 球出し○ | F4: 球出し× | G4: 相手反則 | H4: 被TO | I4: 筑波反則 | L4: =A4 -> 筑波 | N4: 1st | Q4: 2nd
A5: SC | B5: 1st | C5: =SUM(E5:I5) -> 1 | D5: =(E5+F5+G5)/C5 -> 1 | E5: 1 | F5: 0 | G5: 0 | H5: 0 | I5: 0 | L5: 名前 | M5: AT | N5: 内容 | Q5: FW | R5: AT | S5: 内容
B6: 2nd | C6: =SUM(E6:I6) -> 5 | D6: =(E6+F6+G6)/C6 -> 1 | E6: 1 | F6: 1 | G6: 3 | H6: 0 | I6: 0 | L6: 茨木か | M6: DF | N6: ノットリリースザボール | Q6: 東島 | R6: AT | S6: ノットリリースザボール
B7: Total | C7: =SUM(E7:J7) -> 6 | D7: =(E7+F7+G7)/C7 -> 1 | E7: =E5+E6 -> 2 | F7: =F5+F6 -> 1 | G7: =G5+G6 -> 3 | H7: =H5+H6 -> 0 | I7: =I5+I6 -> 0 | L7: 磯部 | M7: DF | N7: ラインオフサイド | Q7: 湯浅 | R7: DF | S7: ノットロールアウェイ
J8: NS | L8: 茨木そ | M8: DF | N8: ハイタックル | Q8: 湯浅 | R8: DF | S8: オフフィート
A9: LO | B9: 1st | C9: =SUM(E9:J9) -> 7 | D9: =(E9+F9+G9)/C9 -> 0.28571429 | E9: 2 | F9: 0 | G9: 0 | H9: 1 | I9: 0 | J9: 4 | L9: FW | M9: DF | N9: SCコラプシング | Q9: 大内田 | R9: DF | S9: ハンド
B10: 2nd | C10: =SUM(E10:J10) -> 12 | D10: =(E10+F10+G10)/C10 -> 0.91666667 | E10: 9 | F10: 2 | G10: 0 | H10: 1 | I10: 0 | J10: 0 | L10: FW | M10: DF | N10: アーリーエンゲージ | Q10: 浜浦 | R10: AT | S10: ノットリリースザボール
B11: Total | C11: =SUM(E11:J11) -> 19 | D11: =(E11+F11+G11)/C11 -> 0.68421053 | E11: =E9+E10 -> 11 | F11: =F9+F10 -> 2 | G11: =G9+G10 -> 0 | H11: =H9+H10 -> 2 | I11: =I9+I10 -> 0 | J11: =J9+J10 -> 4 | L11: FW | M11: DF | N11: SCコラプシング
L12: 白丸 | M12: DF | N12: ホールディング
L13: 磯部 | M13: DF | N13: ハイタックル
A14: =B1 -> 帝京大学 | C14: 総数 | D14: 獲得率 | E14: 球出し○ | F14: 球出し× | G14: 筑波反則 | H14: TO | I14: 相手反則 | L14: 楢本 | M14: DF | N14: ノットロールアウェイ
A15: SC | B15: 1st | C15: =SUM(E15:I15) -> 7 | D15: =(E15+F15+G15)/C15 -> 0.85714286 | E15: 2 | F15: 1 | G15: 3 | H15: 0 | I15: 1
B16: 2nd | C16: =SUM(E16:I16) -> 1 | D16: =(E16+F16+G16)/C16 -> 1 | E16: 1 | F16: 0 | G16: 0 | H16: 0 | I16: 0 | L16: =B1 -> 帝京大学 | N16: 1st
B17: Total | C17: =SUM(E17:I17) -> 8 | D17: =(E17+F17+G17)/C17 -> 0.875 | E17: =E15+E16 -> 3 | F17: =F15+F16 -> 1 | G17: =G15+G16 -> 3 | H17: =H15+H16 -> 0 | I17: =I15+I16 -> 1 | M17: AT | N17: SCコラプシング | R17: DF | S17: SCコラプシング
J18: コンテスト | M18: DF | N18: ハイタックル | R18: AT | S18: ノットリリースザボール
A19: LO | B19: 1st | C19: =SUM(E19:I19) -> 10 | D19: =(E19+F19+G19)/C19 -> 0.5 | E19: 4 | F19: 1 | G19: 0 | H19: 4 | I19: 1 | J19: 4 | R19: DF | S19: アーリープッシュ
B20: 2nd | C20: =SUM(E20:I20) -> 8 | D20: =(E20+F20+G20)/C20 -> 0.625 | E20: 3 | F20: 2 | G20: 0 | H20: 1 | I20: 2 | J20: 4 | R20: DF | S20: SCコラプシング
B21: Total | C21: =SUM(E21:I21) -> 18 | D21: =(E21+F21+G21)/C21 -> 0.55555556 | E21: =E19+E20 -> 7 | F21: =F19+F20 -> 3 | G21: =G19+G20 -> 0 | H21: =H19+H20 -> 5 | I21: =I19+I20 -> 3 | J21: =J19+J20 -> 8 | R21: AT | S21: オブストラクション | Z21: ]
H22: コンテスト率 | J22: =J21/C21 -> 0.44444444 | R22: DF | S22: ハイタックル
R23: DF | S23: ラインオフサイド
L27: Handling Error
L28: =A30 -> 筑波 | N28: 1st | Q28: 2nd
A29: Possession lost | L29: 高橋 | M29: AT[ | N29: パスミス | Q29: 茨木そ | R29: AT | S29: 被インターセプト
A30: 筑波 | C30: 1st | E30: 2nd | G30: Total | I30: ％ | L30: 大内田 | M30: AT[ | N30: ノックフォワード | Q30: 楢本 | R30: AT | S30: 被インターセプト
A31: Set | C31: 5 | E31: 2 | G31: =C31+E31 -> 7 | I31: =G31/G37 -> 0.23333333 | L31: 大内田 | M31: AT[ | N31: ノックフォワード | Q31: 深田 | R31: AT | S31: 被リップ
A32: Ruck & Maul | C32: 0 | E32: 2 | G32: =C32+E32 -> 2 | I32: =G32/G37 -> 0.066666667 | Q32: 浜浦 | R32: AT | S32: パスミス
A33: Handling Error | C33: 3 | E33: 6 | G33: =C33+E33 -> 9 | I33: =G33/G37 -> 0.3 | Q33: 深田 | R33: AT | S33: ノックフォワード
A34: Kick | C34: 10 | E34: 2 | G34: =C34+E34 -> 12 | I34: =G34/G37 -> 0.4 | Q34: 深田 | R34: AT | S34: パスミス
A35: Others | C35: 0 | E35: 0 | G35: =C35+E35 -> 0 | I35: =G35/G37 -> 0
G37: =SUM(G31:H35) -> 30
A38: =B1 -> 帝京大学 | C38: 1st | E38: 2nd | G38: Total | I38: ％ | L38: =B1 -> 帝京大学 | N38: 1st | Q38: 2nd
A39: Set | C39: 5 | E39: 2 | G39: =C39+E39 -> 7 | I39: =G39/H44 -> 0.23333333 | M39: AT | N39: ノックフォワード | R39: AT | S39: ノックフォワード
A40: Ruck & Maul | C40: 2 | E40: 3 | G40: =C40+E40 -> 5 | I40: =G40/H44 -> 0.16666667 | R40: AT | S40: ノックフォワード
A41: Handling Error | C41: 1 | E41: 4 | G41: =C41+E41 -> 5 | I41: =G41/H44 -> 0.16666667 | R41: AT | S41: パスミス
A42: Kick | C42: 8 | E42: 3 | G42: =C42+E42 -> 11 | I42: =G42/H44 -> 0.36666667 | R42: AT | S42: ノックフォワード
A43: Others | C43: 1 | E43: 1 | G43: =C43+E43 -> 2 | I43: =G43/H44 -> 0.066666667
H44: =SUM(G39:H43) -> 30

Sheet Summary 1206_vs青山学院
D3: 筑波大学 | I3: 60 | K3: - | M3: 15 | O3: 青山学院大学 | U3: 12月6日 | Y3: 熊谷B | AC3: 13:00 Kick Off | AG3: 原 大雅
D5: Contact AT STATS | U5: Contact DF STATS
D7: Team Stats | U7: Team Stats
D9: ゲイン | J9: 継続 | P9: B2 | U9: タックル | Y9: Defeat | AC9: Contest | AG9: ゲイン
E14: =E17 -> 13 | F14: =G17-E17 -> 32 | K14: =K17 -> 60 | L14: =M17-K17 -> 12 | Q14: =Q17 -> 19 | R14: =S17-Q17 -> 47 | V14: =V17 -> 78 | W14: =X17-V17 -> 6 | Z14: =Z17 -> 10 | AA14: =AB17-Z17 -> 74 | AD14: =AD17 -> 19 | AE14: =AF17-AD17 -> 18 | AH14: =AH17 -> 15 | AI14: =AJ17-AH17 -> 9
D16: =E17/G17 -> 0.28888889 | J16: =K17/M17 -> 0.83333333 | P16: =Q17/S17 -> 0.28787879 | U16: =V17/X17 -> 0.92857143 | Y16: =Z17/AB17 -> 0.11904762 | AC16: =AD17/AF17 -> 0.51351351 | AG16: =AH17/AJ17 -> 0.625
D17: 成功 | E17: =J22+M22+P22 -> 13 | F17: 母数 | G17: =J23+M23+P23 -> 45 | J17: 成功 | K17: =J26+M26+P26+S26 -> 60 | L17: 母数 | M17: =J27+M27+P27+S27 -> 72 | P17: 成功 | Q17: =M30 -> 19 | R17: 母数 | S17: 66 | U17: 成功 | V17: ='Individual DF 1206_vs青山学院'!K34+'Individual DF 1206_vs青山学院'!L34+'Individual DF 1206_vs青山学院'!T34+'Individual DF 1206_vs青山学院'!U34 -> 78 | W17: 母数 | X17: ='Individual DF 1206_vs青山学院'!G34 -> 84 | Y17: 成功 | Z17: ='Individual DF 1206_vs青山学院'!K34+'Individual DF 1206_vs青山学院'!T34 -> 10 | AA17: 母数 | AB17: ='Individual DF 1206_vs青山学院'!G34 -> 84 | AC17: 成功 | AD17: 19 | AE17: 母数 | AF17: 37 | AG17: 成功 | AH17: 15 | AI17: 母数 | AJ17: 24
D19: Detail Stats | U19: Detail Stats
D21: ゲイン | H21: 9Shape | K21: 10Shape | N21: LineAttack | Q21: Line Atatack(1phase) | U21: タックル | Y21: FW | AB21: BK
G22: 成功 | H22: =J22/J23 -> 0.23076923 | J22: 6 | K22: =M22/M23 -> 0.14285714 | M22: 1 | N22: =P22/P23 -> 0.5 | P22: 6 | Q22: ー | S22: - | X22: 成功 | Y22: =AA22/AA23 -> 0.98214286 | AA22: ='Individual DF 1206_vs青山学院'!K32+'Individual DF 1206_vs青山学院'!L32+'Individual DF 1206_vs青山学院'!T32+'Individual DF 1206_vs青山学院'!U32 -> 55 | AB22: =AD22/AD23 -> 0.82142857 | AD22: ='Individual DF 1206_vs青山学院'!K33+'Individual DF 1206_vs青山学院'!L33+'Individual DF 1206_vs青山学院'!T33+'Individual DF 1206_vs青山学院'!U33 -> 23
G23: 母数 | J23: 26 | M23: 7 | P23: 12 | S23: - | X23: 母数 | AA23: ='Individual DF 1206_vs青山学院'!G32 -> 56 | AD23: ='Individual DF 1206_vs青山学院'!G33 -> 28
D25: 継続 | H25: 9Shape | K25: 10Shape | N25: LineAttack | Q25: Line Atatack(1phase) | U25: Defeat | Y25: FW | AB25: BK
G26: 成功 | H26: =J26/J27 -> 0.96153846 | J26: 25 | K26: =M26/M27 -> 0.85714286 | M26: 6 | N26: =P26/P27 -> 0.66666667 | P26: 8 | Q26: =S26/S27 -> 0.77777778 | S26: 21 | X26: 成功 | Y26: =AA26/AA27 -> 0.035714286 | AA26: ='Individual DF 1206_vs青山学院'!K32+'Individual DF 1206_vs青山学院'!T32 -> 2 | AB26: =AD26/AD27 -> 0.28571429 | AD26: ='Individual DF 1206_vs青山学院'!K33+'Individual DF 1206_vs青山学院'!T33 -> 8
G27: 母数 | J27: 26 | M27: 7 | P27: 12 | S27: 27 | X27: 母数 | AA27: ='Individual DF 1206_vs青山学院'!G32 -> 56 | AD27: ='Individual DF 1206_vs青山学院'!G33 -> 28
D29: B2,3 | H29: B3 | K29: B2 | N29: - | Q29: -
G30: 成功 | H30: =J30/J31 -> 0.6969697 | J30: 46 | K30: =M30/M31 -> 0.28787879 | M30: 19 | N30: - | P30: - | Q30: - | S30: -
G31: 母数 | J31: 66 | M31: 66 | P31: - | S31: -
D34: Set Play Stats
D36: SC Stats | U36: LO Stats
D38: SC | L38: SC マイボールキープ率 | U38: LO | AC38: LO マイボールキープ率
H39: =D3 -> 筑波大学 | J39: ='Set 1206_vs青山学院'!C7 -> 5 | L39: =D3 -> 筑波大学 | P39: =O3 -> 青山学院大学 | Y39: =D3 -> 筑波大学 | AA39: ='Set 1206_vs青山学院'!C11 -> 17 | AC39: =D3 -> 筑波大学 | AG39: =O3 -> 青山学院大学
L41: ='Set 1206_vs青山学院'!D7 -> 0.8 | P41: ='Set 1206_vs青山学院'!D17 -> 0.8 | AC41: ='Set 1206_vs青山学院'!D11 -> 0.88235294 | AG41: ='Set 1206_vs青山学院'!D21 -> 0.63636364
H42: =O3 -> 青山学院大学 | J42: ='Set 1206_vs青山学院'!C17 -> 5 | Y42: =O3 -> 青山学院大学 | AA42: ='Set 1206_vs青山学院'!C21 -> 11
E43: =J39 -> 5 | F43: =J42 -> 5 | V43: =AA39 -> 17 | W43: =AA42 -> 11
H45: Total | J45: =J39+J42 -> 10 | Y45: Total | AA45: =AA39+AA42 -> 28
D46: =J39/J45 -> 0.5 | U46: =AA39/AA45 -> 0.60714286

Sheet Individual DF 1206_vs青山学院
B2: vs | C2: ='Summary 1206_vs青山学院'!O3 -> 青山学院大学 | F2: Individual DF Stats | V2: 分析担当 | Z2: Tackle | AB2: 中矢陸
B4: Team Stats | E4: 総タックル | H4: =G34 -> 84 | J4: Defeat成功率 | M4: =(K34+T34)/G34 -> 0.11904762 | O4: タックル成功率 | R4: =SUM(K34:L34,T34:U34)/G34 -> 0.92857143 | U4: リアクション | X4: 1st | AA4: =SUM(O34:P34)/SUM(K34:L34) -> 0.75609756 | AB4: Assist | AE4: =SUM(X32:Y32)/SUM(T32:U32) -> 0.77777778
I6: 1st Tackle | N6: 1st Tackle Reaction | R6: Assist Tackle | W6: Assist Tackle Reaction | AA6: BD Works
D7: 出場時間 | E7: プレー総数 | F7: プレー換算値 | G7: タックル数 | H7: ％ | I7: 合計 | J7: ％ | K7: ◎ Defeat | L7: ○ 倒す | M7: × 失敗 | N7: % | O7: ファイト | P7: リロード | Q7: × | R7: 合計 | S7: ％ | T7: ◎ Defeat | U7: ○ 倒す | V7: × 失敗 | W7: % | X7: ファイト | Y7: リロード | Z7: × | AA7: 合計 | AB7: % | AC7: Jackal,Jerk | AD7: Pressure | AE7: BD Work × | AF7: 選手名
B8: 1 | C8: 湯浅大心 | D8: 55 | E8: =G8+AA8+'Individual AT 1206_vs青山学院'!G8+'Individual AT 1206_vs青山学院'!N8 -> 13 | F8: =IFERROR(E8/D8*80,"-") -> 18.909091 | G8: =I8+R8 -> 4 | H8: =IFERROR((K8+L8+T8+U8)/G8,"-") -> 1 | I8: =SUM(K8:M8) -> 2 | J8: =IFERROR((K8+L8)/I8,"-") -> 1 | K8: 0 | L8: 2 | M8: 0 | N8: =IFERROR((O8+P8)/I8,"-") -> 1 | O8: 0 | P8: 2 | Q8: 0 | R8: =SUM(T8:V8) -> 2 | S8: =IFERROR((T8+U8)/R8,"-") -> 1 | T8: 0 | U8: 2 | V8: 0 | W8: =IFERROR((X8+Y8)/R8,"-") -> 1 | X8: 1 | Y8: 1 | Z8: 0 | AA8: 0 | AB8: =IFERROR((AC8+AD8)/AA8,"-") -> - | AC8: 1 | AD8: 2 | AE8: 1 | AF8: =C8 -> 湯浅大心
B9: 2 | C9: 前川陽来 | D9: 69 | E9: =G9+AA9+'Individual AT 1206_vs青山学院'!G9+'Individual AT 1206_vs青山学院'!N9 -> 21 | F9: =IFERROR(E9/D9*80,"-") -> 24.347826 | G9: =I9+R9 -> 8 | H9: =IFERROR((K9+L9+T9+U9)/G9,"-") -> 1 | I9: =SUM(K9:M9) -> 3 | J9: =IFERROR((K9+L9)/I9,"-") -> 1 | K9: 0 | L9: 3 | M9: 0 | N9: =IFERROR((O9+P9)/I9,"-") -> 0.66666667 | O9: 0 | P9: 2 | Q9: 1 | R9: =SUM(T9:V9) -> 5 | S9: =IFERROR((T9+U9)/R9,"-") -> 1 | T9: 1 | U9: 4 | V9: 0 | W9: =IFERROR((X9+Y9)/R9,"-") -> 0.6 | X9: 2 | Y9: 1 | Z9: 2 | AA9: =SUM(AC9:AE9) -> 0 | AB9: =IFERROR((AC9+AD9)/AA9,"-") -> - | AC9: 0 | AD9: 0 | AE9: 0 | AF9: =C9 -> 前川陽来
B10: 3 | C10: イーゴリ | D10: 55 | E10: =G10+AA10+'Individual AT 1206_vs青山学院'!G10+'Individual AT 1206_vs青山学院'!N10 -> 20 | F10: =IFERROR(E10/D10*80,"-") -> 29.090909 | G10: =I10+R10 -> 8 | H10: =IFERROR((K10+L10+T10+U10)/G10,"-") -> 1 | I10: =SUM(K10:M10) -> 4 | J10: =IFERROR((K10+L10)/I10,"-") -> 1 | K10: 0 | L10: 4 | M10: 0 | N10: =IFERROR((O10+P10)/I10,"-") -> 0.75 | O10: 0 | P10: 3 | Q10: 1 | R10: =SUM(T10:V10) -> 4 | S10: =IFERROR((T10+U10)/R10,"-") -> 1 | T10: 0 | U10: 4 | V10: 0 | W10: =IFERROR((X10+Y10)/R10,"-") -> 0.75 | X10: 0 | Y10: 3 | Z10: 1 | AA10: =SUM(AC10:AE10) -> 3 | AB10: =IFERROR((AC10+AD10)/AA10,"-") -> 0.66666667 | AC10: 1 | AD10: 1 | AE10: 1 | AF10: =C10 -> イーゴリ
B11: 4 | C11: 磯部俊太朗 | D11: 77 | E11: =G11+AA11+'Individual AT 1206_vs青山学院'!G11+'Individual AT 1206_vs青山学院'!N11 -> 19 | F11: =IFERROR(E11/D11*80,"-") -> 19.74026 | G11: =I11+R11 -> 3 | H11: =IFERROR((K11+L11+T11+U11)/G11,"-") -> 1 | I11: =SUM(K11:M11) -> 2 | J11: =IFERROR((K11+L11)/I11,"-") -> 1 | K11: 0 | L11: 2 | M11: 0 | N11: =IFERROR((O11+P11)/I11,"-") -> 0.5 | O11: 0 | P11: 1 | Q11: 1 | R11: =SUM(T11:V11) -> 1 | S11: =IFERROR((T11+U11)/R11,"-") -> 1 | T11: 0 | U11: 1 | V11: 0 | W11: =IFERROR((X11+Y11)/R11,"-") -> 1 | X11: 1 | Y11: 0 | Z11: 0 | AA11: =SUM(AC11:AE11) -> 1 | AB11: =IFERROR((AC11+AD11)/AA11,"-") -> 1 | AC11: 0 | AD11: 1 | AE11: 0 | AF11: =C11 -> 磯部俊太朗
B12: 5 | C12: 白丸智乃祐 | D12: 82 | E12: =G12+AA12+'Individual AT 1206_vs青山学院'!G12+'Individual AT 1206_vs青山学院'!N12 -> 27 | F12: =IFERROR(E12/D12*80,"-") -> 26.341463 | G12: =I12+R12 -> 4 | H12: =IFERROR((K12+L12+T12+U12)/G12,"-") -> 1 | I12: =SUM(K12:M12) -> 1 | J12: =IFERROR((K12+L12)/I12,"-") -> 1 | K12: 0 | L12: 1 | M12: 0 | N12: =IFERROR((O12+P12)/I12,"-") -> 0 | O12: 0 | P12: 0 | Q12: 1 | R12: =SUM(T12:V12) -> 3 | S12: =IFERROR((T12+U12)/R12,"-") -> 1 | T12: 1 | U12: 2 | V12: 0 | W12: =IFERROR((X12+Y12)/R12,"-") -> 0.33333333 | X12: 0 | Y12: 1 | Z12: 2 | AA12: =SUM(AC12:AE12) -> 3 | AB12: =IFERROR((AC12+AD12)/AA12,"-") -> 0.66666667 | AC12: 0 | AD12: 2 | AE12: 1 | AF12: =C12 -> 白丸智乃祐
B13: 6 | C13: 茨木颯 | D13: 82 | E13: =G13+AA13+'Individual AT 1206_vs青山学院'!G13+'Individual AT 1206_vs青山学院'!N13 -> 32 | F13: =IFERROR(E13/D13*80,"-") -> 31.219512 | G13: =I13+R13 -> 6 | H13: =IFERROR((K13+L13+T13+U13)/G13,"-") -> 1 | I13: =SUM(K13:M13) -> 4 | J13: =IFERROR((K13+L13)/I13,"-") -> 1 | K13: 0 | L13: 4 | M13: 0 | N13: =IFERROR((O13+P13)/I13,"-") -> 0.5 | O13: 1 | P13: 1 | Q13: 2 | R13: =SUM(T13:V13) -> 2 | S13: =IFERROR((T13+U13)/R13,"-") -> 1 | T13: 0 | U13: 2 | V13: 0 | W13: =IFERROR((X13+Y13)/R13,"-") -> 1 | X13: 1 | Y13: 1 | Z13: 0 | AA13: =SUM(AC13:AE13) -> 6 | AB13: =IFERROR((AC13+AD13)/AA13,"-") -> 1 | AC13: 2 | AD13: 4 | AE13: 0 | AF13: =C13 -> 茨木颯
B14: 7 | C14: 大町尚生 | D14: 82 | E14: =G14+AA14+'Individual AT 1206_vs青山学院'!G14+'Individual AT 1206_vs青山学院'!N14 -> 39 | F14: =IFERROR(E14/D14*80,"-") -> 38.04878 | G14: =I14+R14 -> 10 | H14: =IFERROR((K14+L14+T14+U14)/G14,"-") -> 1 | I14: =SUM(K14:M14) -> 6 | J14: =IFERROR((K14+L14)/I14,"-") -> 1 | K14: 0 | L14: 6 | M14: 0 | N14: =IFERROR((O14+P14)/I14,"-") -> 0.66666667 | O14: 0 | P14: 4 | Q14: 2 | R14: =SUM(T14:V14) -> 4 | S14: =IFERROR((T14+U14)/R14,"-") -> 1 | T14: 0 | U14: 4 | V14: 0 | W14: =IFERROR((X14+Y14)/R14,"-") -> 0.75 | X14: 1 | Y14: 2 | Z14: 1 | AA14: =SUM(AC14:AE14) -> 1 | AB14: =IFERROR((AC14+AD14)/AA14,"-") -> 1 | AC14: 1 | AD14: 0 | AE14: 0 | AF14: =C14 -> 大町尚生
B15: 8 | C15: 浜浦幸太郎 | D15: 61 | E15: =G15+AA15+'Individual AT 1206_vs青山学院'!G15+'Individual AT 1206_vs青山学院'!N15 -> 28 | F15: =IFERROR(E15/D15*80,"-") -> 36.721311 | G15: =I15+R15 -> 8 | H15: =IFERROR((K15+L15+T15+U15)/G15,"-") -> 1 | I15: =SUM(K15:M15) -> 4 | J15: =IFERROR((K15+L15)/I15,"-") -> 1 | K15: 0 | L15: 4 | M15: 0 | N15: =IFERROR((O15+P15)/I15,"-") -> 0.5 | O15: 0 | P15: 2 | Q15: 2 | R15: =SUM(T15:V15) -> 4 | S15: =IFERROR((T15+U15)/R15,"-") -> 1 | T15: 0 | U15: 4 | V15: 0 | W15: =IFERROR((X15+Y15)/R15,"-") -> 1 | X15: 1 | Y15: 3 | Z15: 0 | AA15: =SUM(AC15:AE15) -> 2 | AB15: =IFERROR((AC15+AD15)/AA15,"-") -> 1 | AC15: 1 | AD15: 1 | AE15: 0 | AF15: =C15 -> 浜浦幸太郎
B16: 9 | C16: 高橋佑太朗 | D16: 70 | E16: =G16+AA16+'Individual AT 1206_vs青山学院'!G16+'Individual AT 1206_vs青山学院'!N16 -> 4 | F16: =IFERROR(E16/D16*80,"-") -> 4.5714286 | G16: =I16+R16 -> 1 | H16: =IFERROR((K16+L16+T16+U16)/G16,"-") -> 1 | I16: =SUM(K16:M16) -> 1 | J16: =IFERROR((K16+L16)/I16,"-") -> 1 | K16: 0 | L16: 1 | M16: 0 | N16: =IFERROR((O16+P16)/I16,"-") -> 1 | O16: 0 | P16: 1 | Q16: 0 | R16: =SUM(T16:V16) -> 0 | S16: =IFERROR((T16+U16)/R16,"-") -> - | T16: 0 | U16: 0 | V16: 0 | W16: =IFERROR((X16+Y16)/R16,"-") -> - | X16: 0 | Y16: 0 | Z16: 0 | AA16: =SUM(AC16:AE16) -> 0 | AB16: =IFERROR((AC16+AD16)/AA16,"-") -> - | AC16: 0 | AD16: 0 | AE16: 0 | AF16: =C16 -> 高橋佑太朗
B17: 10 | C17: 楢本幹志朗 | D17: 82 | E17: =G17+AA17+'Individual AT 1206_vs青山学院'!G17+'Individual AT 1206_vs青山学院'!N17 -> 8 | F17: =IFERROR(E17/D17*80,"-") -> 7.804878 | G17: =I17+R17 -> 2 | H17: =IFERROR((K17+L17+T17+U17)/G17,"-") -> 0.5 | I17: =SUM(K17:M17) -> 2 | J17: =IFERROR((K17+L17)/I17,"-") -> 0.5 | K17: 0 | L17: 1 | M17: 1 | N17: =IFERROR((O17+P17)/I17,"-") -> 0.5 | O17: 0 | P17: 1 | Q17: 0 | R17: =SUM(T17:V17) -> 0 | S17: =IFERROR((T17+U17)/R17,"-") -> - | T17: 0 | U17: 0 | V17: 0 | W17: =IFERROR((X17+Y17)/R17,"-") -> - | X17: 0 | Y17: 0 | Z17: 0 | AA17: =SUM(AC17:AE17) -> 0 | AB17: =IFERROR((AC17+AD17)/AA17,"-") -> - | AC17: 0 | AD17: 0 | AE17: 0 | AF17: =C17 -> 楢本幹志朗
B18: 11 | C18: 林勇太 | D18: 77 | E18: =G18+AA18+'Individual AT 1206_vs青山学院'!G18+'Individual AT 1206_vs青山学院'!N18 -> 17 | F18: =IFERROR(E18/D18*80,"-") -> 17.662338 | G18: =I18+R18 -> 3 | H18: =IFERROR((K18+L18+T18+U18)/G18,"-") -> 1 | I18: =SUM(K18:M18) -> 3 | J18: =IFERROR((K18+L18)/I18,"-") -> 1 | K18: 2 | L18: 1 | M18: 0 | N18: =IFERROR((O18+P18)/I18,"-") -> 1 | O18: 0 | P18: 3 | Q18: 0 | R18: =SUM(T18:V18) -> 0 | S18: =IFERROR((T18+U18)/R18,"-") -> - | T18: 0 | U18: 0 | V18: 0 | W18: =IFERROR((X18+Y18)/R18,"-") -> - | X18: 0 | Y18: 0 | Z18: 0 | AA18: =SUM(AC18:AE18) -> 0 | AB18: =IFERROR((AC18+AD18)/AA18,"-") -> - | AC18: 0 | AD18: 0 | AE18: 0 | AF18: =C18 -> 林勇太
B19: 12 | C19: 朴大優 | D19: 82 | E19: =G19+AA19+'Individual AT 1206_vs青山学院'!G19+'Individual AT 1206_vs青山学院'!N19 -> 27 | F19: =IFERROR(E19/D19*80,"-") -> 26.341463 | G19: =I19+R19 -> 8 | H19: =IFERROR((K19+L19+T19+U19)/G19,"-") -> 0.875 | I19: =SUM(K19:M19) -> 3 | J19: =IFERROR((K19+L19)/I19,"-") -> 1 | K19: 1 | L19: 2 | M19: 0 | N19: =IFERROR((O19+P19)/I19,"-") -> 1 | O19: 1 | P19: 2 | Q19: 0 | R19: =SUM(T19:V19) -> 5 | S19: =IFERROR((T19+U19)/R19,"-") -> 0.8 | T19: 1 | U19: 3 | V19: 1 | W19: =IFERROR((X19+Y19)/R19,"-") -> 0.8 | X19: 0 | Y19: 4 | Z19: 0 | AA19: =SUM(AC19:AE19) -> 1 | AB19: =IFERROR((AC19+AD19)/AA19,"-") -> 1 | AC19: 1 | AD19: 0 | AE19: 0 | AF19: =C19 -> 朴大優
B20: 13 | C20: 東島和哉 | D20: 63 | E20: =G20+AA20+'Individual AT 1206_vs青山学院'!G20+'Individual AT 1206_vs青山学院'!N20 -> 12 | F20: =IFERROR(E20/D20*80,"-") -> 15.238095 | G20: =I20+R20 -> 4 | H20: =IFERROR((K20+L20+T20+U20)/G20,"-") -> 1 | I20: =SUM(K20:M20) -> 2 | J20: =IFERROR((K20+L20)/I20,"-") -> 1 | K20: 1 | L20: 1 | M20: 0 | N20: =IFERROR((O20+P20)/I20,"-") -> 1 | O20: 0 | P20: 2 | Q20: 0 | R20: =SUM(T20:V20) -> 2 | S20: =IFERROR((T20+U20)/R20,"-") -> 1 | T20: 1 | U20: 1 | V20: 0 | W20: =IFERROR((X20+Y20)/R20,"-") -> 1 | X20: 0 | Y20: 2 | Z20: 0 | AA20: =SUM(AC20:AE20) -> 0 | AB20: =IFERROR((AC20+AD20)/AA20,"-") -> - | AC20: 0 | AD20: 0 | AE20: 0 | AF20: =C20 -> 東島和哉
... B30: 23 | C30: 今村颯汰 | D30: 5 | E30: =G30+AA30+'Individual AT 1206_vs青山学院'!G30+'Individual AT 1206_vs青山学院'!N30 -> 2 | F30: =IFERROR(E30/D30*80,"-") -> 32 | G30: =I30+R30 -> 0 | H30: =IFERROR((K30+L30+T30+U30)/G30,"-") -> - | I30: =SUM(K30:M30) -> 0 | J30: =IFERROR((K30+L30)/I30,"-") -> - | K30: 0 | L30: 0 | M30: 0 | N30: =IFERROR((O30+P30)/I30,"-") -> - | O30: 0 | P30: 0 | Q30: 0 | R30: =SUM(T30:V30) -> 0 | S30: =IFERROR((T30+U30)/R30,"-") -> - | T30: 0 | U30: 0 | V30: 0 | W30: =IFERROR((X30+Y30)/R30,"-") -> - | X30: 0 | Y30: 0 | Z30: 0 | AA30: =SUM(AC30:AE30) -> 0 | AB30: =IFERROR((AC30+AD30)/AA30,"-") -> - | AC30: 0 | AD30: 0 | AE30: 0 | AF30: =C30 -> 今村颯汰
B32: FW Total | G32: =SUM(G8:G15,G23:G27) -> 56 | I32: =SUM(I8:I15,I23:I27) -> 29 | J32: =SUM(K32:L32)/I32 -> 0.96551724 | K32: =SUM(K8:K15,K23:K27) -> 0 | L32: =SUM(L8:L15,L23:L27) -> 28 | M32: =SUM(M8:M15,M23:M27) -> 1 | N32: =SUM(O32:P32)/I32 -> 0.62068966 | O32: =SUM(O8:O15,O23:O27) -> 1 | P32: =SUM(P8:P15,P23:P27) -> 17 | Q32: =SUM(Q8:Q15,Q23:Q27) -> 10 | R32: =SUM(R8:R15,R23:R27) -> 27 | S32: =SUM(T32:U32)/R32 -> 1 | T32: =SUM(T8:T15,T23:T27) -> 2 | U32: =SUM(U8:U15,U23:U27) -> 25 | V32: =SUM(V8:V15,V23:V27) -> 0 | W32: =SUM(X32:Y32)/SUM(X32:Z32) -> 0.77777778 | X32: =SUM(X8:X15,X23:X27) -> 8 | Y32: =SUM(Y8:Y15,Y23:Y27) -> 13 | Z32: =SUM(Z8:Z15,Z23:Z27) -> 6 | AA32: =SUM(AA8:AA15,AA23:AA27) -> 16 | AB32: =SUM(AC32:AD32)/SUM(AC32:AE32) -> 0.85 | AC32: =SUM(AC8:AC15,AC23:AC27) -> 6 | AD32: =SUM(AD8:AD15,AD23:AD27) -> 11 | AE32: =SUM(AE8:AE15,AE23:AE27) -> 3 | AF32: FW Total
B33: BK Total | G33: =SUM(G16:G22,G28:G30) -> 28 | I33: =SUM(I16:I22,I28:I30) -> 17 | J33: =SUM(K33:L33)/I33 -> 0.76470588 | K33: =SUM(K16:K22,K28:K30) -> 6 | L33: =SUM(L16:L22,L28:L30) -> 7 | M33: =SUM(M16:M22,M28:M30) -> 4 | N33: =SUM(O33:P33)/I33 -> 0.76470588 | O33: =SUM(O16:O22,O28:O30) -> 1 | P33: =SUM(P16:P22,P28:P30) -> 12 | Q33: =SUM(Q16:Q22,Q28:Q30) -> 0 | R33: =SUM(R16:R22,R28:R30) -> 11 | S33: =SUM(T33:U33)/R33 -> 0.90909091 | T33: =SUM(T16:T22,T28:T30) -> 2 | U33: =SUM(U16:U22,U28:U30) -> 8 | V33: =SUM(V16:V22,V28:V30) -> 1 | W33: =SUM(X33:Y33)/SUM(X33:Z33) -> 0.9 | X33: =SUM(X16:X22,X28:X30) -> 1 | Y33: =SUM(Y16:Y22,Y28:Y30) -> 8 | Z33: =SUM(Z16:Z22,Z28:Z30) -> 1 | AA33: =SUM(AA16:AA22,AA28:AA30) -> 1 | AB33: =SUM(AC33:AD33)/SUM(AC33:AE33) -> 1 | AC33: =SUM(AC16:AC22,AC28:AC30) -> 1 | AD33: =SUM(AD16:AD22,AD28:AD30) -> 0 | AE33: =SUM(AE16:AE22,AE28:AE30) -> 0 | AF33: BK Total
B34: Team Total | G34: =SUM(G8:G30) -> 84 | I34: =SUM(I8:I30) -> 46 | J34: =SUM(K34:L34)/I34 -> 0.89130435 | K34: =SUM(K8:K30) -> 6 | L34: =SUM(L8:L30) -> 35 | M34: =SUM(M8:M30) -> 5 | N34: =SUM(O34:P34)/I34 -> 0.67391304 | O34: =SUM(O8:O30) -> 2 | P34: =SUM(P8:P30) -> 29 | Q34: =SUM(Q8:Q30) -> 10 | R34: =SUM(R8:R30) -> 38 | S34: =SUM(T34:U34)/R34 -> 0.97368421 | T34: =SUM(T8:T30) -> 4 | U34: =SUM(U8:U30) -> 33 | V34: =SUM(V8:V30) -> 1 | W34: =SUM(X34:Y34)/SUM(X34:Z34) -> 0.81081081 | X34: =SUM(X8:X30) -> 9 | Y34: =SUM(Y8:Y30) -> 21 | Z34: =SUM(Z8:Z30) -> 7 | AA34: =SUM(AA8:AA30) -> 17 | AB34: =SUM(AC34:AD34)/SUM(AC34:AE34) -> 0.85714286 | AC34: =SUM(AC8:AC30) -> 7 | AD34: =SUM(AD8:AD30) -> 11 | AE34: =SUM(AE8:AE30) -> 3 | AF34: Team Total
B35: Team Average | G35: =AVERAGE(G8:G30) -> 3.6521739 | I35: =AVERAGE(I8:I30) -> 2 | K35: =AVERAGE(K8:K30) -> 0.26086957 | L35: =AVERAGE(L8:L30) -> 1.5217391 | M35: =AVERAGE(M8:M30) -> 0.2173913 | O35: =AVERAGE(O8:O30) -> 0.086956522 | P35: =AVERAGE(P8:P30) -> 1.2608696 | Q35: =AVERAGE(Q8:Q30) -> 0.43478261 | R35: =AVERAGE(R8:R30) -> 1.6521739 | T35: =AVERAGE(T8:T30) -> 0.17391304 | U35: =AVERAGE(U8:U30) -> 1.4347826 | V35: =AVERAGE(V8:V30) -> 0.043478261 | X35: =AVERAGE(X8:X30) -> 0.39130435 | Y35: =AVERAGE(Y8:Y30) -> 0.91304348 | Z35: =AVERAGE(Z8:Z30) -> 0.30434783 | AA35: =AVERAGE(AA8:AA30) -> 0.73913043 | AC35: =AVERAGE(AC8:AC30) -> 0.30434783 | AD35: =AVERAGE(AD8:AD30) -> 0.47826087 | AE35: =AVERAGE(AE8:AE30) -> 0.13043478 | AF35: Team Average

Sheet Individual AT 1206_vs青山学院
B2: vs | C2: ='Summary 1206_vs青山学院'!O3 -> 青山学院大学 | F2: Individual AT Stats | O2: 分析担当 | S2: 表 | Y2: B2,3 | AA2: 中矢陸
B4: Team Stats | E4: Body Ball Control | J4: =H34 -> 0.90789474 | N4: Support | R4: =O34 -> 0.95454545 | U4: B3 | X4: =T34 -> 0.86818182 | Z4: B2 | AC4: =Z34 -> 0.68636364
G6: Carrier Contact | N6: Support | S6: B3 | Y6: B2
D7: 出場時間 | E7: プレー総数 | F7: プレー換算値 | G7: 合計 | H7: Good/Stay ％ | I7: BB% | J7: Gain◎ | K7: Stay○ | L7: 後退△ | M7: Lost× | N7: 合計 | O7: ％ | P7: EXELLENT◎ | Q7: GOOD○ | R7: BAD× | S7: 合計 | T7: ％ | U7: Carrier○ | V7: Carrier× | W7: Support○ | X7: Support× | Y7: 合計 | Z7: ％ | AA7: Carrier○ | AB7: Carrier× | AC7: Support○ | AD7: Support× | AE7: 選手名
B8: 1 | C8: ='Individual DF 1206_vs青山学院'!C8 -> 湯浅大心 | D8: ='Individual DF 1206_vs青山学院'!D8 -> 55 | E8: ='Individual DF 1206_vs青山学院'!E8 -> 13 | F8: ='Individual DF 1206_vs青山学院'!F8 -> 18.909091 | G8: =SUM(J8:M8) -> 5 | H8: =IFERROR((J8+K8)/SUM(J8:M8),"-") -> 1 | I8: =IFERROR(SUM(J8:L8)/SUM(J8:M8),"-") -> 1 | J8: 1 | K8: 4 | L8: 0 | M8: 0 | N8: =SUM(P8:R8) -> 4 | O8: =IFERROR((P8+Q8)/N8,"-") -> 0.75 | P8: 0 | Q8: 3 | R8: 1 | S8: =SUM(U8:X8) -> 7 | T8: =IFERROR((U8+W8)/S8,"-") -> 0.71428571 | U8: 3 | V8: 1 | W8: 2 | X8: 1 | Y8: =SUM(AA8:AD8) -> 7 | Z8: =IFERROR((AA8+AC8)/Y8,"-") -> 0.42857143 | AA8: 1 | AB8: 3 | AC8: 2 | AD8: 1 | AE8: =C8 -> 湯浅大心
B9: 2 | C9: ='Individual DF 1206_vs青山学院'!C9 -> 前川陽来 | D9: ='Individual DF 1206_vs青山学院'!D9 -> 69 | E9: ='Individual DF 1206_vs青山学院'!E9 -> 21 | F9: ='Individual DF 1206_vs青山学院'!F9 -> 24.347826 | G9: =SUM(J9:M9) -> 2 | H9: =IFERROR((J9+K9)/SUM(J9:M9),"-") -> 1 | I9: =IFERROR(SUM(J9:L9)/SUM(J9:M9),"-") -> 1 | J9: 0 | K9: 2 | L9: 0 | M9: 0 | N9: =SUM(P9:R9) -> 11 | O9: =IFERROR((P9+Q9)/N9,"-") -> 1 | P9: 2 | Q9: 9 | R9: 0 | S9: =SUM(U9:X9) -> 13 | T9: =IFERROR((U9+W9)/S9,"-") -> 1 | U9: 2 | V9: 0 | W9: 11 | X9: 0 | Y9: =SUM(AA9:AD9) -> 13 | Z9: =IFERROR((AA9+AC9)/Y9,"-") -> 0.84615385 | AA9: 0 | AB9: 2 | AC9: 11 | AD9: 0 | AE9: =C9 -> 前川陽来
B10: 3 | C10: ='Individual DF 1206_vs青山学院'!C10 -> イーゴリ | D10: ='Individual DF 1206_vs青山学院'!D10 -> 55 | E10: ='Individual DF 1206_vs青山学院'!E10 -> 20 | F10: ='Individual DF 1206_vs青山学院'!F10 -> 29.090909 | G10: =SUM(J10:M10) -> 2 | H10: =IFERROR((J10+K10)/SUM(J10:M10),"-") -> 1 | I10: =IFERROR(SUM(J10:L10)/SUM(J10:M10),"-") -> 1 | J10: 0 | K10: 2 | L10: 0 | M10: 0 | N10: =SUM(P10:R10) -> 7 | O10: =IFERROR((P10+Q10)/N10,"-") -> 0.85714286 | P10: 0 | Q10: 6 | R10: 1 | S10: =SUM(U10:X10) -> 10 | T10: =IFERROR((U10+W10)/S10,"-") -> 0.7 | U10: 0 | V10: 2 | W10: 7 | X10: 1 | Y10: =SUM(AA10:AD10) -> 10 | Z10: =IFERROR((AA10+AC10)/Y10,"-") -> 0.5 | AA10: 0 | AB10: 2 | AC10: 5 | AD10: 3 | AE10: =C10 -> イーゴリ
B11: 4 | C11: ='Individual DF 1206_vs青山学院'!C11 -> 磯部俊太朗 | D11: ='Individual DF 1206_vs青山学院'!D11 -> 77 | E11: ='Individual DF 1206_vs青山学院'!E11 -> 19 | F11: ='Individual DF 1206_vs青山学院'!F11 -> 19.74026 | G11: =SUM(J11:M11) -> 5 | H11: =IFERROR((J11+K11)/SUM(J11:M11),"-") -> 1 | I11: =IFERROR(SUM(J11:L11)/SUM(J11:M11),"-") -> 1 | J11: 2 | K11: 3 | L11: 0 | M11: 0 | N11: =SUM(P11:R11) -> 10 | O11: =IFERROR((P11+Q11)/N11,"-") -> 1 | P11: 1 | Q11: 9 | R11: 0 | S11: =SUM(U11:X11) -> 14 | T11: =IFERROR((U11+W11)/S11,"-") -> 0.85714286 | U11: 3 | V11: 2 | W11: 9 | X11: 0 | Y11: =SUM(AA11:AD11) -> 14 | Z11: =IFERROR((AA11+AC11)/Y11,"-") -> 0.5 | AA11: 1 | AB11: 4 | AC11: 6 | AD11: 3 | AE11: =C11 -> 磯部俊太朗
B12: 5 | C12: ='Individual DF 1206_vs青山学院'!C12 -> 白丸智乃祐 | D12: ='Individual DF 1206_vs青山学院'!D12 -> 82 | E12: ='Individual DF 1206_vs青山学院'!E12 -> 27 | F12: ='Individual DF 1206_vs青山学院'!F12 -> 26.341463 | G12: =SUM(J12:M12) -> 3 | H12: =IFERROR((J12+K12)/SUM(J12:M12),"-") -> 1 | I12: =IFERROR(SUM(J12:L12)/SUM(J12:M12),"-") -> 1 | J12: 0 | K12: 3 | L12: 0 | M12: 0 | N12: =SUM(P12:R12) -> 17 | O12: =IFERROR((P12+Q12)/N12,"-") -> 1 | P12: 2 | Q12: 15 | R12: 0 | S12: =SUM(U12:X12) -> 13 | T12: =IFERROR((U12+W12)/S12,"-") -> 1 | U12: 3 | V12: 0 | W12: 10 | X12: 0 | Y12: =SUM(AA12:AD12) -> 13 | Z12: =IFERROR((AA12+AC12)/Y12,"-") -> 0.84615385 | AA12: 2 | AB12: 1 | AC12: 9 | AD12: 1 | AE12: =C12 -> 白丸智乃祐
B13: 6 | C13: ='Individual DF 1206_vs青山学院'!C13 -> 茨木颯 | D13: ='Individual DF 1206_vs青山学院'!D13 -> 82 | E13: ='Individual DF 1206_vs青山学院'!E13 -> 32 | F13: ='Individual DF 1206_vs青山学院'!F13 -> 31.219512 | G13: =SUM(J13:M13) -> 6 | H13: =IFERROR((J13+K13)/SUM(J13:M13),"-") -> 1 | I13: =IFERROR(SUM(J13:L13)/SUM(J13:M13),"-") -> 1 | J13: 1 | K13: 5 | L13: 0 | M13: 0 | N13: =SUM(P13:R13) -> 14 | O13: =IFERROR((P13+Q13)/N13,"-") -> 0.92857143 | P13: 0 | Q13: 13 | R13: 1 | S13: =SUM(U13:X13) -> 19 | T13: =IFERROR((U13+W13)/S13,"-") -> 0.73684211 | U13: 1 | V13: 4 | W13: 13 | X13: 1 | Y13: =SUM(AA13:AD13) -> 19 | Z13: =IFERROR((AA13+AC13)/Y13,"-") -> 0.63157895 | AA13: 0 | AB13: 5 | AC13: 12 | AD13: 2 | AE13: =C13 -> 茨木颯
B14: 7 | C14: ='Individual DF 1206_vs青山学院'!C14 -> 大町尚生 | D14: ='Individual DF 1206_vs青山学院'!D14 -> 82 | E14: ='Individual DF 1206_vs青山学院'!E14 -> 39 | F14: ='Individual DF 1206_vs青山学院'!F14 -> 38.04878 | G14: =SUM(J14:M14) -> 4 | H14: =IFERROR((J14+K14)/SUM(J14:M14),"-") -> 1 | I14: =IFERROR(SUM(J14:L14)/SUM(J14:M14),"-") -> 1 | J14: 1 | K14: 3 | L14: 0 | M14: 0 | N14: =SUM(P14:R14) -> 24 | O14: =IFERROR((P14+Q14)/N14,"-") -> 0.95833333 | P14: 2 | Q14: 21 | R14: 1 | S14: =SUM(U14:X14) -> 24 | T14: =IFERROR((U14+W14)/S14,"-") -> 0.91666667 | U14: 2 | V14: 1 | W14: 20 | X14: 1 | Y14: =SUM(AA14:AD14) -> 24 | Z14: =IFERROR((AA14+AC14)/Y14,"-") -> 0.83333333 | AA14: 1 | AB14: 2 | AC14: 19 | AD14: 2 | AE14: =C14 -> 大町尚生
B15: 8 | C15: ='Individual DF 1206_vs青山学院'!C15 -> 浜浦幸太郎 | D15: ='Individual DF 1206_vs青山学院'!D15 -> 61 | E15: ='Individual DF 1206_vs青山学院'!E15 -> 28 | F15: ='Individual DF 1206_vs青山学院'!F15 -> 36.721311 | G15: =SUM(J15:M15) -> 8 | H15: =IFERROR((J15+K15)/SUM(J15:M15),"-") -> 0.875 | I15: =IFERROR(SUM(J15:L15)/SUM(J15:M15),"-") -> 1 | J15: 2 | K15: 5 | L15: 1 | M15: 0 | N15: =SUM(P15:R15) -> 10 | O15: =IFERROR((P15+Q15)/N15,"-") -> 0.9 | P15: 1 | Q15: 8 | R15: 1 | S15: =SUM(U15:X15) -> 15 | T15: =IFERROR((U15+W15)/S15,"-") -> 0.73333333 | U15: 6 | V15: 2 | W15: 5 | X15: 2 | Y15: =SUM(AA15:AD15) -> 15 | Z15: =IFERROR((AA15+AC15)/Y15,"-") -> 0.4 | AA15: 1 | AB15: 7 | AC15: 5 | AD15: 2 | AE15: =C15 -> 浜浦幸太郎
B16: 9 | C16: ='Individual DF 1206_vs青山学院'!C16 -> 高橋佑太朗 | D16: ='Individual DF 1206_vs青山学院'!D16 -> 70 | E16: ='Individual DF 1206_vs青山学院'!E16 -> 4 | F16: ='Individual DF 1206_vs青山学院'!F16 -> 4.5714286 | G16: =SUM(J16:M16) -> 1 | H16: =IFERROR((J16+K16)/SUM(J16:M16),"-") -> 1 | I16: =IFERROR(SUM(J16:L16)/SUM(J16:M16),"-") -> 1 | J16: 0 | K16: 1 | L16: 0 | M16: 0 | N16: =SUM(P16:R16) -> 2 | O16: =IFERROR((P16+Q16)/N16,"-") -> 1 | P16: 0 | Q16: 2 | R16: 0 | S16: =SUM(U16:X16) -> 2 | T16: =IFERROR((U16+W16)/S16,"-") -> 1 | U16: 1 | V16: 0 | W16: 1 | X16: 0 | Y16: =SUM(AA16:AD16) -> 2 | Z16: =IFERROR((AA16+AC16)/Y16,"-") -> 0.5 | AA16: 0 | AB16: 1 | AC16: 1 | AD16: 0 | AE16: =C16 -> 高橋佑太朗
B17: 10 | C17: ='Individual DF 1206_vs青山学院'!C17 -> 楢本幹志朗 | D17: ='Individual DF 1206_vs青山学院'!D17 -> 82 | E17: ='Individual DF 1206_vs青山学院'!E17 -> 8 | F17: ='Individual DF 1206_vs青山学院'!F17 -> 7.804878 | G17: =SUM(J17:M17) -> 6 | H17: =IFERROR((J17+K17)/SUM(J17:M17),"-") -> 0.66666667 | I17: =IFERROR(SUM(J17:L17)/SUM(J17:M17),"-") -> 0.66666667 | J17: 1 | K17: 3 | L17: 0 | M17: 2 | N17: =SUM(P17:R17) -> 0 | O17: =IFERROR((P17+Q17)/N17,"-") -> - | P17: 0 | Q17: 0 | R17: 0 | S17: =SUM(U17:X17) -> 3 | T17: =IFERROR((U17+W17)/S17,"-") -> 0.33333333 | U17: 1 | V17: 2 | W17: 0 | X17: 0 | Y17: =SUM(AA17:AD17) -> 3 | Z17: =IFERROR((AA17+AC17)/Y17,"-") -> 0 | AA17: 0 | AB17: 3 | AC17: 0 | AD17: 0 | AE17: =C17 -> 楢本幹志朗
